LAST SEEN   TYPE      REASON                         OBJECT                                     MESSAGE
28m         Warning   NodeNotReady                   pod/aws-node-48t5z                         Node is not ready
54m         Normal    Scheduled                      pod/aws-node-4gtff                         Successfully assigned kube-system/aws-node-4gtff to ip-10-1-52-192.eu-west-3.compute.internal
54m         Normal    Pulling                        pod/aws-node-4gtff                         Pulling image "602401143452.dkr.ecr.eu-west-3.amazonaws.com/amazon-k8s-cni-init:v1.10.1-eksbuild.1"
54m         Normal    Pulled                         pod/aws-node-4gtff                         Successfully pulled image "602401143452.dkr.ecr.eu-west-3.amazonaws.com/amazon-k8s-cni-init:v1.10.1-eksbuild.1" in 9.392611983s
54m         Normal    Created                        pod/aws-node-4gtff                         Created container aws-vpc-cni-init
54m         Normal    Started                        pod/aws-node-4gtff                         Started container aws-vpc-cni-init
54m         Normal    Pulling                        pod/aws-node-4gtff                         Pulling image "602401143452.dkr.ecr.eu-west-3.amazonaws.com/amazon-k8s-cni:v1.10.1-eksbuild.1"
54m         Normal    Pulled                         pod/aws-node-4gtff                         Successfully pulled image "602401143452.dkr.ecr.eu-west-3.amazonaws.com/amazon-k8s-cni:v1.10.1-eksbuild.1" in 2.538912283s
54m         Normal    Created                        pod/aws-node-4gtff                         Created container aws-node
54m         Normal    Started                        pod/aws-node-4gtff                         Started container aws-node
40m         Normal    ScaleDown                      pod/aws-node-4gtff                         deleting pod for node scale down
40m         Normal    Killing                        pod/aws-node-4gtff                         Stopping container aws-node
21m         Normal    Scheduled                      pod/aws-node-7hqlb                         Successfully assigned kube-system/aws-node-7hqlb to ip-10-1-62-180.eu-west-3.compute.internal
21m         Normal    Pulling                        pod/aws-node-7hqlb                         Pulling image "602401143452.dkr.ecr.eu-west-3.amazonaws.com/amazon-k8s-cni-init:v1.10.1-eksbuild.1"
21m         Normal    Pulled                         pod/aws-node-7hqlb                         Successfully pulled image "602401143452.dkr.ecr.eu-west-3.amazonaws.com/amazon-k8s-cni-init:v1.10.1-eksbuild.1" in 9.522026934s
21m         Normal    Created                        pod/aws-node-7hqlb                         Created container aws-vpc-cni-init
21m         Normal    Started                        pod/aws-node-7hqlb                         Started container aws-vpc-cni-init
21m         Normal    Pulling                        pod/aws-node-7hqlb                         Pulling image "602401143452.dkr.ecr.eu-west-3.amazonaws.com/amazon-k8s-cni:v1.10.1-eksbuild.1"
21m         Normal    Pulled                         pod/aws-node-7hqlb                         Successfully pulled image "602401143452.dkr.ecr.eu-west-3.amazonaws.com/amazon-k8s-cni:v1.10.1-eksbuild.1" in 2.487414524s
21m         Normal    Created                        pod/aws-node-7hqlb                         Created container aws-node
21m         Normal    Started                        pod/aws-node-7hqlb                         Started container aws-node
21m         Warning   Unhealthy                      pod/aws-node-7hqlb                         Readiness probe failed: {"level":"info","ts":"2022-09-02T16:23:09.496Z","caller":"/usr/local/go/src/runtime/proc.go:225","msg":"timeout: failed to connect service \":50051\" within 5s"}
28m         Warning   NodeNotReady                   pod/aws-node-9trg4                         Node is not ready
48m         Normal    Scheduled                      pod/aws-node-bt6h6                         Successfully assigned kube-system/aws-node-bt6h6 to ip-10-1-1-25.eu-west-3.compute.internal
48m         Normal    Pulling                        pod/aws-node-bt6h6                         Pulling image "602401143452.dkr.ecr.eu-west-3.amazonaws.com/amazon-k8s-cni-init:v1.10.1-eksbuild.1"
48m         Normal    Pulled                         pod/aws-node-bt6h6                         Successfully pulled image "602401143452.dkr.ecr.eu-west-3.amazonaws.com/amazon-k8s-cni-init:v1.10.1-eksbuild.1" in 9.953530453s
48m         Normal    Created                        pod/aws-node-bt6h6                         Created container aws-vpc-cni-init
48m         Normal    Started                        pod/aws-node-bt6h6                         Started container aws-vpc-cni-init
48m         Normal    Pulling                        pod/aws-node-bt6h6                         Pulling image "602401143452.dkr.ecr.eu-west-3.amazonaws.com/amazon-k8s-cni:v1.10.1-eksbuild.1"
48m         Normal    Pulled                         pod/aws-node-bt6h6                         Successfully pulled image "602401143452.dkr.ecr.eu-west-3.amazonaws.com/amazon-k8s-cni:v1.10.1-eksbuild.1" in 2.694583932s
48m         Normal    Created                        pod/aws-node-bt6h6                         Created container aws-node
48m         Normal    Started                        pod/aws-node-bt6h6                         Started container aws-node
38m         Warning   NodeNotReady                   pod/aws-node-bt6h6                         Node is not ready
21m         Normal    Scheduled                      pod/aws-node-hg6k2                         Successfully assigned kube-system/aws-node-hg6k2 to ip-10-1-12-138.eu-west-3.compute.internal
21m         Normal    Pulling                        pod/aws-node-hg6k2                         Pulling image "602401143452.dkr.ecr.eu-west-3.amazonaws.com/amazon-k8s-cni-init:v1.10.1-eksbuild.1"
21m         Normal    Pulled                         pod/aws-node-hg6k2                         Successfully pulled image "602401143452.dkr.ecr.eu-west-3.amazonaws.com/amazon-k8s-cni-init:v1.10.1-eksbuild.1" in 9.861632359s
21m         Normal    Created                        pod/aws-node-hg6k2                         Created container aws-vpc-cni-init
21m         Normal    Started                        pod/aws-node-hg6k2                         Started container aws-vpc-cni-init
21m         Normal    Pulling                        pod/aws-node-hg6k2                         Pulling image "602401143452.dkr.ecr.eu-west-3.amazonaws.com/amazon-k8s-cni:v1.10.1-eksbuild.1"
21m         Normal    Pulled                         pod/aws-node-hg6k2                         Successfully pulled image "602401143452.dkr.ecr.eu-west-3.amazonaws.com/amazon-k8s-cni:v1.10.1-eksbuild.1" in 2.994806995s
21m         Normal    Created                        pod/aws-node-hg6k2                         Created container aws-node
21m         Normal    Started                        pod/aws-node-hg6k2                         Started container aws-node
14m         Normal    ScaleDown                      pod/aws-node-hg6k2                         deleting pod for node scale down
14m         Normal    Killing                        pod/aws-node-hg6k2                         Stopping container aws-node
39m         Normal    Scheduled                      pod/aws-node-hndgn                         Successfully assigned kube-system/aws-node-hndgn to ip-10-1-52-192.eu-west-3.compute.internal
39m         Normal    Pulled                         pod/aws-node-hndgn                         Container image "602401143452.dkr.ecr.eu-west-3.amazonaws.com/amazon-k8s-cni-init:v1.10.1-eksbuild.1" already present on machine
39m         Normal    Created                        pod/aws-node-hndgn                         Created container aws-vpc-cni-init
39m         Normal    Started                        pod/aws-node-hndgn                         Started container aws-vpc-cni-init
39m         Normal    Pulled                         pod/aws-node-hndgn                         Container image "602401143452.dkr.ecr.eu-west-3.amazonaws.com/amazon-k8s-cni:v1.10.1-eksbuild.1" already present on machine
39m         Normal    Created                        pod/aws-node-hndgn                         Created container aws-node
39m         Normal    Started                        pod/aws-node-hndgn                         Started container aws-node
38m         Warning   NodeNotReady                   pod/aws-node-hndgn                         Node is not ready
21m         Normal    Scheduled                      pod/aws-node-jhnw2                         Successfully assigned kube-system/aws-node-jhnw2 to ip-10-1-0-97.eu-west-3.compute.internal
21m         Normal    Pulling                        pod/aws-node-jhnw2                         Pulling image "602401143452.dkr.ecr.eu-west-3.amazonaws.com/amazon-k8s-cni-init:v1.10.1-eksbuild.1"
21m         Normal    Pulled                         pod/aws-node-jhnw2                         Successfully pulled image "602401143452.dkr.ecr.eu-west-3.amazonaws.com/amazon-k8s-cni-init:v1.10.1-eksbuild.1" in 9.662116531s
21m         Normal    Created                        pod/aws-node-jhnw2                         Created container aws-vpc-cni-init
21m         Normal    Started                        pod/aws-node-jhnw2                         Started container aws-vpc-cni-init
21m         Normal    Pulling                        pod/aws-node-jhnw2                         Pulling image "602401143452.dkr.ecr.eu-west-3.amazonaws.com/amazon-k8s-cni:v1.10.1-eksbuild.1"
21m         Normal    Pulled                         pod/aws-node-jhnw2                         Successfully pulled image "602401143452.dkr.ecr.eu-west-3.amazonaws.com/amazon-k8s-cni:v1.10.1-eksbuild.1" in 2.621903785s
21m         Normal    Created                        pod/aws-node-jhnw2                         Created container aws-node
21m         Normal    Started                        pod/aws-node-jhnw2                         Started container aws-node
21m         Warning   Unhealthy                      pod/aws-node-jhnw2                         Readiness probe failed: {"level":"info","ts":"2022-09-02T16:23:05.215Z","caller":"/usr/local/go/src/runtime/proc.go:225","msg":"timeout: failed to connect service \":50051\" within 5s"}
21m         Normal    Scheduled                      pod/aws-node-k8l9n                         Successfully assigned kube-system/aws-node-k8l9n to ip-10-1-51-246.eu-west-3.compute.internal
21m         Normal    Pulling                        pod/aws-node-k8l9n                         Pulling image "602401143452.dkr.ecr.eu-west-3.amazonaws.com/amazon-k8s-cni-init:v1.10.1-eksbuild.1"
21m         Normal    Pulled                         pod/aws-node-k8l9n                         Successfully pulled image "602401143452.dkr.ecr.eu-west-3.amazonaws.com/amazon-k8s-cni-init:v1.10.1-eksbuild.1" in 9.41826527s
21m         Normal    Created                        pod/aws-node-k8l9n                         Created container aws-vpc-cni-init
21m         Normal    Started                        pod/aws-node-k8l9n                         Started container aws-vpc-cni-init
21m         Normal    Pulling                        pod/aws-node-k8l9n                         Pulling image "602401143452.dkr.ecr.eu-west-3.amazonaws.com/amazon-k8s-cni:v1.10.1-eksbuild.1"
21m         Normal    Pulled                         pod/aws-node-k8l9n                         Successfully pulled image "602401143452.dkr.ecr.eu-west-3.amazonaws.com/amazon-k8s-cni:v1.10.1-eksbuild.1" in 2.506147858s
21m         Normal    Created                        pod/aws-node-k8l9n                         Created container aws-node
21m         Normal    Started                        pod/aws-node-k8l9n                         Started container aws-node
56m         Normal    ScaleDown                      pod/aws-node-lg977                         deleting pod for node scale down
56m         Normal    Killing                        pod/aws-node-lg977                         Stopping container aws-node
38m         Normal    Scheduled                      pod/aws-node-p2j82                         Successfully assigned kube-system/aws-node-p2j82 to ip-10-1-38-3.eu-west-3.compute.internal
38m         Normal    Pulling                        pod/aws-node-p2j82                         Pulling image "602401143452.dkr.ecr.eu-west-3.amazonaws.com/amazon-k8s-cni-init:v1.10.1-eksbuild.1"
38m         Normal    Pulled                         pod/aws-node-p2j82                         Successfully pulled image "602401143452.dkr.ecr.eu-west-3.amazonaws.com/amazon-k8s-cni-init:v1.10.1-eksbuild.1" in 9.49351089s
38m         Normal    Created                        pod/aws-node-p2j82                         Created container aws-vpc-cni-init
38m         Normal    Started                        pod/aws-node-p2j82                         Started container aws-vpc-cni-init
38m         Normal    Pulling                        pod/aws-node-p2j82                         Pulling image "602401143452.dkr.ecr.eu-west-3.amazonaws.com/amazon-k8s-cni:v1.10.1-eksbuild.1"
38m         Normal    Pulled                         pod/aws-node-p2j82                         Successfully pulled image "602401143452.dkr.ecr.eu-west-3.amazonaws.com/amazon-k8s-cni:v1.10.1-eksbuild.1" in 2.493610536s
37m         Normal    Created                        pod/aws-node-p2j82                         Created container aws-node
37m         Normal    Started                        pod/aws-node-p2j82                         Started container aws-node
28m         Warning   NodeNotReady                   pod/aws-node-p2j82                         Node is not ready
14m         Normal    Scheduled                      pod/aws-node-thtgs                         Successfully assigned kube-system/aws-node-thtgs to ip-10-1-12-138.eu-west-3.compute.internal
14m         Normal    Pulled                         pod/aws-node-thtgs                         Container image "602401143452.dkr.ecr.eu-west-3.amazonaws.com/amazon-k8s-cni-init:v1.10.1-eksbuild.1" already present on machine
14m         Normal    Created                        pod/aws-node-thtgs                         Created container aws-vpc-cni-init
14m         Normal    Started                        pod/aws-node-thtgs                         Started container aws-vpc-cni-init
14m         Normal    Pulled                         pod/aws-node-thtgs                         Container image "602401143452.dkr.ecr.eu-west-3.amazonaws.com/amazon-k8s-cni:v1.10.1-eksbuild.1" already present on machine
14m         Normal    Created                        pod/aws-node-thtgs                         Created container aws-node
14m         Normal    Started                        pod/aws-node-thtgs                         Started container aws-node
13m         Warning   NodeNotReady                   pod/aws-node-thtgs                         Node is not ready
55m         Warning   NodeNotReady                   pod/aws-node-v2bvx                         Node is not ready
12m         Normal    Scheduled                      pod/aws-node-vh7bk                         Successfully assigned kube-system/aws-node-vh7bk to ip-10-1-26-106.eu-west-3.compute.internal
12m         Normal    Pulling                        pod/aws-node-vh7bk                         Pulling image "602401143452.dkr.ecr.eu-west-3.amazonaws.com/amazon-k8s-cni-init:v1.10.1-eksbuild.1"
12m         Normal    Pulled                         pod/aws-node-vh7bk                         Successfully pulled image "602401143452.dkr.ecr.eu-west-3.amazonaws.com/amazon-k8s-cni-init:v1.10.1-eksbuild.1" in 10.215540679s
12m         Normal    Created                        pod/aws-node-vh7bk                         Created container aws-vpc-cni-init
12m         Normal    Started                        pod/aws-node-vh7bk                         Started container aws-vpc-cni-init
12m         Normal    Pulling                        pod/aws-node-vh7bk                         Pulling image "602401143452.dkr.ecr.eu-west-3.amazonaws.com/amazon-k8s-cni:v1.10.1-eksbuild.1"
12m         Normal    Pulled                         pod/aws-node-vh7bk                         Successfully pulled image "602401143452.dkr.ecr.eu-west-3.amazonaws.com/amazon-k8s-cni:v1.10.1-eksbuild.1" in 2.764584039s
12m         Normal    Created                        pod/aws-node-vh7bk                         Created container aws-node
12m         Normal    Started                        pod/aws-node-vh7bk                         Started container aws-node
28m         Warning   NodeNotReady                   pod/aws-node-vj8dr                         Node is not ready
56m         Normal    Scheduled                      pod/aws-node-xhjpf                         Successfully assigned kube-system/aws-node-xhjpf to ip-10-1-34-180.eu-west-3.compute.internal
56m         Normal    Pulled                         pod/aws-node-xhjpf                         Container image "602401143452.dkr.ecr.eu-west-3.amazonaws.com/amazon-k8s-cni-init:v1.10.1-eksbuild.1" already present on machine
56m         Normal    Created                        pod/aws-node-xhjpf                         Created container aws-vpc-cni-init
56m         Normal    Started                        pod/aws-node-xhjpf                         Started container aws-vpc-cni-init
56m         Normal    Pulled                         pod/aws-node-xhjpf                         Container image "602401143452.dkr.ecr.eu-west-3.amazonaws.com/amazon-k8s-cni:v1.10.1-eksbuild.1" already present on machine
56m         Normal    Created                        pod/aws-node-xhjpf                         Created container aws-node
56m         Normal    Started                        pod/aws-node-xhjpf                         Started container aws-node
56m         Warning   Unhealthy                      pod/aws-node-xhjpf                         Readiness probe failed: {"level":"info","ts":"2022-09-02T15:47:59.790Z","caller":"/usr/local/go/src/runtime/proc.go:225","msg":"timeout: failed to connect service \":50051\" within 5s"}
55m         Warning   NodeNotReady                   pod/aws-node-xhjpf                         Node is not ready
35m         Normal    Scheduled                      pod/aws-node-xkvs6                         Successfully assigned kube-system/aws-node-xkvs6 to ip-10-1-32-108.eu-west-3.compute.internal
34m         Normal    Pulling                        pod/aws-node-xkvs6                         Pulling image "602401143452.dkr.ecr.eu-west-3.amazonaws.com/amazon-k8s-cni-init:v1.10.1-eksbuild.1"
34m         Normal    Pulled                         pod/aws-node-xkvs6                         Successfully pulled image "602401143452.dkr.ecr.eu-west-3.amazonaws.com/amazon-k8s-cni-init:v1.10.1-eksbuild.1" in 9.300581082s
34m         Normal    Created                        pod/aws-node-xkvs6                         Created container aws-vpc-cni-init
34m         Normal    Started                        pod/aws-node-xkvs6                         Started container aws-vpc-cni-init
34m         Normal    Pulling                        pod/aws-node-xkvs6                         Pulling image "602401143452.dkr.ecr.eu-west-3.amazonaws.com/amazon-k8s-cni:v1.10.1-eksbuild.1"
34m         Normal    Pulled                         pod/aws-node-xkvs6                         Successfully pulled image "602401143452.dkr.ecr.eu-west-3.amazonaws.com/amazon-k8s-cni:v1.10.1-eksbuild.1" in 2.490353905s
34m         Normal    Created                        pod/aws-node-xkvs6                         Created container aws-node
34m         Normal    Started                        pod/aws-node-xkvs6                         Started container aws-node
28m         Warning   NodeNotReady                   pod/aws-node-xkvs6                         Node is not ready
21m         Normal    Scheduled                      pod/aws-node-xnzgm                         Successfully assigned kube-system/aws-node-xnzgm to ip-10-1-37-225.eu-west-3.compute.internal
21m         Normal    Pulling                        pod/aws-node-xnzgm                         Pulling image "602401143452.dkr.ecr.eu-west-3.amazonaws.com/amazon-k8s-cni-init:v1.10.1-eksbuild.1"
21m         Normal    Pulled                         pod/aws-node-xnzgm                         Successfully pulled image "602401143452.dkr.ecr.eu-west-3.amazonaws.com/amazon-k8s-cni-init:v1.10.1-eksbuild.1" in 9.974627916s
21m         Normal    Created                        pod/aws-node-xnzgm                         Created container aws-vpc-cni-init
21m         Normal    Started                        pod/aws-node-xnzgm                         Started container aws-vpc-cni-init
21m         Normal    Pulling                        pod/aws-node-xnzgm                         Pulling image "602401143452.dkr.ecr.eu-west-3.amazonaws.com/amazon-k8s-cni:v1.10.1-eksbuild.1"
21m         Normal    Pulled                         pod/aws-node-xnzgm                         Successfully pulled image "602401143452.dkr.ecr.eu-west-3.amazonaws.com/amazon-k8s-cni:v1.10.1-eksbuild.1" in 2.736922965s
21m         Normal    Created                        pod/aws-node-xnzgm                         Created container aws-node
21m         Normal    Started                        pod/aws-node-xnzgm                         Started container aws-node
21m         Warning   Unhealthy                      pod/aws-node-xnzgm                         Readiness probe failed: {"level":"info","ts":"2022-09-02T16:23:07.470Z","caller":"/usr/local/go/src/runtime/proc.go:225","msg":"timeout: failed to connect service \":50051\" within 5s"}
12m         Warning   NodeNotReady                   pod/aws-node-xnzgm                         Node is not ready
56m         Normal    SuccessfulCreate               daemonset/aws-node                         Created pod: aws-node-xhjpf
54m         Normal    SuccessfulCreate               daemonset/aws-node                         Created pod: aws-node-4gtff
48m         Normal    SuccessfulCreate               daemonset/aws-node                         Created pod: aws-node-bt6h6
39m         Normal    SuccessfulCreate               daemonset/aws-node                         Created pod: aws-node-hndgn
35m         Normal    SuccessfulCreate               daemonset/aws-node                         (combined from similar events): Created pod: aws-node-xkvs6
21m         Normal    SuccessfulCreate               daemonset/aws-node                         Created pod: aws-node-jhnw2
21m         Normal    SuccessfulCreate               daemonset/aws-node                         Created pod: aws-node-hg6k2
21m         Normal    SuccessfulCreate               daemonset/aws-node                         Created pod: aws-node-xnzgm
21m         Normal    SuccessfulCreate               daemonset/aws-node                         Created pod: aws-node-k8l9n
21m         Normal    SuccessfulCreate               daemonset/aws-node                         Created pod: aws-node-7hqlb
14m         Normal    SuccessfulCreate               daemonset/aws-node                         Created pod: aws-node-thtgs
12m         Normal    SuccessfulCreate               daemonset/aws-node                         Created pod: aws-node-vh7bk
20m         Normal    Scheduled                      pod/cluster-autoscaler-5f6f5fd7dc-4zf56    Successfully assigned kube-system/cluster-autoscaler-5f6f5fd7dc-4zf56 to ip-10-1-62-180.eu-west-3.compute.internal
20m         Normal    Pulling                        pod/cluster-autoscaler-5f6f5fd7dc-4zf56    Pulling image "hub.simloudcorp.customers.simloud.com/k8s-artifacts-prod/autoscaling/cluster-autoscaler:v1.21.1"
20m         Normal    Pulled                         pod/cluster-autoscaler-5f6f5fd7dc-4zf56    Successfully pulled image "hub.simloudcorp.customers.simloud.com/k8s-artifacts-prod/autoscaling/cluster-autoscaler:v1.21.1" in 9.127772132s
20m         Normal    Created                        pod/cluster-autoscaler-5f6f5fd7dc-4zf56    Created container cluster-autoscaler
20m         Normal    Started                        pod/cluster-autoscaler-5f6f5fd7dc-4zf56    Started container cluster-autoscaler
19m         Normal    Killing                        pod/cluster-autoscaler-5f6f5fd7dc-4zf56    Stopping container cluster-autoscaler
29m         Normal    Killing                        pod/cluster-autoscaler-5f6f5fd7dc-c4rdb    Stopping container cluster-autoscaler
29m         Normal    SuccessfulDelete               replicaset/cluster-autoscaler-5f6f5fd7dc   Deleted pod: cluster-autoscaler-5f6f5fd7dc-c4rdb
20m         Normal    SuccessfulCreate               replicaset/cluster-autoscaler-5f6f5fd7dc   Created pod: cluster-autoscaler-5f6f5fd7dc-4zf56
19m         Normal    SuccessfulDelete               replicaset/cluster-autoscaler-5f6f5fd7dc   Deleted pod: cluster-autoscaler-5f6f5fd7dc-4zf56
20m         Normal    Scheduled                      pod/cluster-autoscaler-797dc49745-5pk4z    Successfully assigned kube-system/cluster-autoscaler-797dc49745-5pk4z to ip-10-1-0-97.eu-west-3.compute.internal
20m         Normal    Pulling                        pod/cluster-autoscaler-797dc49745-5pk4z    Pulling image "hub.simloudcorp.customers.simloud.com/k8s-artifacts-prod/autoscaling/cluster-autoscaler:v1.21.1"
20m         Normal    Pulled                         pod/cluster-autoscaler-797dc49745-5pk4z    Successfully pulled image "hub.simloudcorp.customers.simloud.com/k8s-artifacts-prod/autoscaling/cluster-autoscaler:v1.21.1" in 9.925299501s
20m         Normal    Created                        pod/cluster-autoscaler-797dc49745-5pk4z    Created container cluster-autoscaler
20m         Normal    Started                        pod/cluster-autoscaler-797dc49745-5pk4z    Started container cluster-autoscaler
20m         Normal    SuccessfulCreate               replicaset/cluster-autoscaler-797dc49745   Created pod: cluster-autoscaler-797dc49745-5pk4z
56m         Normal    ScaleDown                      configmap/cluster-autoscaler-status        Scale-down: removing node ip-10-1-34-180.eu-west-3.compute.internal, utilization: {0.4792746113989637 0.2261777461460521 0 cpu 0.4792746113989637}, pods to reschedule: kube-system/vault-agent-injector-57d87ff44f-qq88s,kube-system/coredns-9b5d74bfb-x6mgf,kube-system/consul-server-2,kube-system/metrics-server-645499f5cf-h969p
49m         Normal    ScaledUpGroup                  configmap/cluster-autoscaler-status        Scale-up: setting group eksctl-Olga-olga-new-1259e40f2-c525-4acc-9849-3983bc91e9b6-nodegroup-61bb1b32-d5dd-4f04-83bb-256a7dd8615c-NodeGroup-1RLXJSW61L9SQ size to 5
40m         Normal    ScaleDown                      configmap/cluster-autoscaler-status        Scale-down: removing node ip-10-1-52-192.eu-west-3.compute.internal, utilization: {0.4792746113989637 0.19326828572797572 0 cpu 0.4792746113989637}, pods to reschedule: kube-system/vault-agent-injector-57d87ff44f-vtsc7,default/micro-service2-5cc8c54dbc-87s2t
14m         Normal    ScaleDown                      configmap/cluster-autoscaler-status        Scale-down: removing node ip-10-1-12-138.eu-west-3.compute.internal, utilization: {0.4274611398963731 0.20523536224363986 0 cpu 0.4274611398963731}, pods to reschedule: kube-system/kubed-6b446694ff-wsknb,kube-system/grafana-b488bf7c-84nwq,kube-system/consul-server-1,kube-system/vault-agent-injector-57d87ff44f-t9mw8
20m         Normal    ScalingReplicaSet              deployment/cluster-autoscaler              Scaled up replica set cluster-autoscaler-5f6f5fd7dc to 1
19m         Normal    ScalingReplicaSet              deployment/cluster-autoscaler              Scaled down replica set cluster-autoscaler-5f6f5fd7dc to 0
20m         Normal    ScalingReplicaSet              deployment/cluster-autoscaler              Scaled up replica set cluster-autoscaler-797dc49745 to 1
19m         Normal    LeaderElection                 lease/cluster-autoscaler                   cluster-autoscaler-797dc49745-5pk4z became leader
12m         Normal    Scheduled                      pod/consul-2bckm                           Successfully assigned kube-system/consul-2bckm to ip-10-1-26-106.eu-west-3.compute.internal
12m         Normal    Pulling                        pod/consul-2bckm                           Pulling image "hub.simloudcorp.customers.simloud.com/hashicorp/consul:1.10.0"
11m         Normal    Pulled                         pod/consul-2bckm                           Successfully pulled image "hub.simloudcorp.customers.simloud.com/hashicorp/consul:1.10.0" in 6.751842092s
11m         Normal    Created                        pod/consul-2bckm                           Created container consul
11m         Normal    Started                        pod/consul-2bckm                           Started container consul
5m18s       Warning   Unhealthy                      pod/consul-2bckm                           Readiness probe failed:
29m         Warning   Unhealthy                      pod/consul-4l5wn                           Readiness probe failed:
29m         Normal    Killing                        pod/consul-4l5wn                           Stopping container consul
20m         Normal    Scheduled                      pod/consul-56fn4                           Successfully assigned kube-system/consul-56fn4 to ip-10-1-0-97.eu-west-3.compute.internal
20m         Normal    Pulling                        pod/consul-56fn4                           Pulling image "hub.simloudcorp.customers.simloud.com/hashicorp/consul:1.10.0"
20m         Normal    Pulled                         pod/consul-56fn4                           Successfully pulled image "hub.simloudcorp.customers.simloud.com/hashicorp/consul:1.10.0" in 14.323043528s
20m         Normal    Created                        pod/consul-56fn4                           Created container consul
20m         Normal    Started                        pod/consul-56fn4                           Started container consul
19m         Warning   Unhealthy                      pod/consul-56fn4                           Readiness probe failed:
56m         Normal    ScaleDown                      pod/consul-6wrlb                           deleting pod for node scale down
56m         Normal    Killing                        pod/consul-6wrlb                           Stopping container consul
47m         Normal    Scheduled                      pod/consul-b2pcs                           Successfully assigned kube-system/consul-b2pcs to ip-10-1-1-25.eu-west-3.compute.internal
47m         Normal    Pulling                        pod/consul-b2pcs                           Pulling image "hub.simloudcorp.customers.simloud.com/hashicorp/consul:1.10.0"
47m         Normal    Pulled                         pod/consul-b2pcs                           Successfully pulled image "hub.simloudcorp.customers.simloud.com/hashicorp/consul:1.10.0" in 6.203569787s
47m         Normal    Created                        pod/consul-b2pcs                           Created container consul
47m         Normal    Started                        pod/consul-b2pcs                           Started container consul
47m         Warning   Unhealthy                      pod/consul-b2pcs                           Readiness probe failed:
38m         Warning   NodeNotReady                   pod/consul-b2pcs                           Node is not ready
36m         Warning   FailedToUpdateEndpoint         endpoints/consul-dns                       Failed to update endpoint kube-system/consul-dns: Operation cannot be fulfilled on endpoints "consul-dns": the object has been modified; please apply your changes to the latest version and try again
53m         Warning   FailedToUpdateEndpointSlices   service/consul-dns                         Error updating Endpoint Slices for Service kube-system/consul-dns: node "ip-10-1-30-25.eu-west-3.compute.internal" not found
37m         Warning   FailedToUpdateEndpointSlices   service/consul-dns                         Error updating Endpoint Slices for Service kube-system/consul-dns: node "ip-10-1-1-25.eu-west-3.compute.internal" not found
11m         Warning   FailedToUpdateEndpointSlices   service/consul-dns                         Error updating Endpoint Slices for Service kube-system/consul-dns: node "ip-10-1-37-225.eu-west-3.compute.internal" not found
55m         Warning   NodeNotReady                   pod/consul-dpgj6                           Node is not ready
20m         Normal    Scheduled                      pod/consul-ld6vw                           Successfully assigned kube-system/consul-ld6vw to ip-10-1-37-225.eu-west-3.compute.internal
20m         Normal    Pulling                        pod/consul-ld6vw                           Pulling image "hub.simloudcorp.customers.simloud.com/hashicorp/consul:1.10.0"
20m         Normal    Pulled                         pod/consul-ld6vw                           Successfully pulled image "hub.simloudcorp.customers.simloud.com/hashicorp/consul:1.10.0" in 9.22366459s
20m         Normal    Created                        pod/consul-ld6vw                           Created container consul
20m         Normal    Started                        pod/consul-ld6vw                           Started container consul
19m         Warning   Unhealthy                      pod/consul-ld6vw                           Readiness probe failed:
12m         Warning   NodeNotReady                   pod/consul-ld6vw                           Node is not ready
29m         Warning   Unhealthy                      pod/consul-p5hvd                           Readiness probe failed:
29m         Normal    Killing                        pod/consul-p5hvd                           Stopping container consul
34m         Normal    Scheduled                      pod/consul-q7hcx                           Successfully assigned kube-system/consul-q7hcx to ip-10-1-32-108.eu-west-3.compute.internal
34m         Normal    Pulling                        pod/consul-q7hcx                           Pulling image "hub.simloudcorp.customers.simloud.com/hashicorp/consul:1.10.0"
34m         Normal    Pulled                         pod/consul-q7hcx                           Successfully pulled image "hub.simloudcorp.customers.simloud.com/hashicorp/consul:1.10.0" in 6.405968522s
34m         Normal    Created                        pod/consul-q7hcx                           Created container consul
34m         Normal    Started                        pod/consul-q7hcx                           Started container consul
34m         Warning   Unhealthy                      pod/consul-q7hcx                           Readiness probe failed:
29m         Normal    Killing                        pod/consul-q7hcx                           Stopping container consul
54m         Normal    Scheduled                      pod/consul-q7hwq                           Successfully assigned kube-system/consul-q7hwq to ip-10-1-52-192.eu-west-3.compute.internal
54m         Normal    Pulling                        pod/consul-q7hwq                           Pulling image "hub.simloudcorp.customers.simloud.com/hashicorp/consul:1.10.0"
54m         Normal    Pulled                         pod/consul-q7hwq                           Successfully pulled image "hub.simloudcorp.customers.simloud.com/hashicorp/consul:1.10.0" in 6.624665756s
54m         Normal    Created                        pod/consul-q7hwq                           Created container consul
54m         Normal    Started                        pod/consul-q7hwq                           Started container consul
47m         Warning   Unhealthy                      pod/consul-q7hwq                           Readiness probe failed:
40m         Normal    ScaleDown                      pod/consul-q7hwq                           deleting pod for node scale down
40m         Normal    Killing                        pod/consul-q7hwq                           Stopping container consul
20m         Normal    Scheduled                      pod/consul-qrqvn                           Successfully assigned kube-system/consul-qrqvn to ip-10-1-51-246.eu-west-3.compute.internal
20m         Normal    Pulling                        pod/consul-qrqvn                           Pulling image "hub.simloudcorp.customers.simloud.com/hashicorp/consul:1.10.0"
20m         Normal    Pulled                         pod/consul-qrqvn                           Successfully pulled image "hub.simloudcorp.customers.simloud.com/hashicorp/consul:1.10.0" in 10.270795849s
20m         Normal    Created                        pod/consul-qrqvn                           Created container consul
20m         Normal    Started                        pod/consul-qrqvn                           Started container consul
19m         Warning   Unhealthy                      pod/consul-qrqvn                           Readiness probe failed:
20m         Normal    Scheduled                      pod/consul-qtx76                           Successfully assigned kube-system/consul-qtx76 to ip-10-1-12-138.eu-west-3.compute.internal
20m         Normal    Pulling                        pod/consul-qtx76                           Pulling image "hub.simloudcorp.customers.simloud.com/hashicorp/consul:1.10.0"
20m         Normal    Pulled                         pod/consul-qtx76                           Successfully pulled image "hub.simloudcorp.customers.simloud.com/hashicorp/consul:1.10.0" in 7.783839172s
20m         Normal    Created                        pod/consul-qtx76                           Created container consul
20m         Normal    Started                        pod/consul-qtx76                           Started container consul
19m         Warning   Unhealthy                      pod/consul-qtx76                           Readiness probe failed:
14m         Normal    ScaleDown                      pod/consul-qtx76                           deleting pod for node scale down
14m         Normal    Killing                        pod/consul-qtx76                           Stopping container consul
56m         Warning   Unhealthy                      pod/consul-server-0                        Readiness probe failed:
29m         Normal    Killing                        pod/consul-server-0                        Stopping container consul
29m         Warning   Unhealthy                      pod/consul-server-0                        Readiness probe failed: OCI runtime exec failed: exec failed: cannot exec in a stopped container: unknown
20m         Normal    Scheduled                      pod/consul-server-0                        Successfully assigned kube-system/consul-server-0 to ip-10-1-62-180.eu-west-3.compute.internal
20m         Normal    SuccessfulAttachVolume         pod/consul-server-0                        AttachVolume.Attach succeeded for volume "pvc-f5c7e541-c4b1-4b8d-8c48-4072339045f5"
20m         Normal    Pulled                         pod/consul-server-0                        Container image "hub.simloudcorp.customers.simloud.com/hashicorp/consul:1.10.0" already present on machine
20m         Normal    Created                        pod/consul-server-0                        Created container consul
20m         Normal    Started                        pod/consul-server-0                        Started container consul
14m         Warning   Unhealthy                      pod/consul-server-0                        Readiness probe failed:
56m         Warning   Unhealthy                      pod/consul-server-1                        Readiness probe failed:
55m         Warning   NodeNotReady                   pod/consul-server-1                        Node is not ready
53m         Warning   FailedAttachVolume             pod/consul-server-1                        AttachVolume.Attach failed for volume "pvc-ce67bb9b-cc8d-472d-86bd-dfaa97683633" : error finding instance ip-10-1-30-25.eu-west-3.compute.internal: "instance not found"
53m         Normal    TaintManagerEviction           pod/consul-server-1                        Cancelling deletion of Pod kube-system/consul-server-1
53m         Normal    Scheduled                      pod/consul-server-1                        Successfully assigned kube-system/consul-server-1 to ip-10-1-9-246.eu-west-3.compute.internal
53m         Normal    SuccessfulAttachVolume         pod/consul-server-1                        AttachVolume.Attach succeeded for volume "pvc-ce67bb9b-cc8d-472d-86bd-dfaa97683633"
53m         Normal    Pulled                         pod/consul-server-1                        Container image "hub.simloudcorp.customers.simloud.com/hashicorp/consul:1.10.0" already present on machine
53m         Normal    Created                        pod/consul-server-1                        Created container consul
53m         Normal    Started                        pod/consul-server-1                        Started container consul
29m         Normal    Killing                        pod/consul-server-1                        Stopping container consul
20m         Normal    Scheduled                      pod/consul-server-1                        Successfully assigned kube-system/consul-server-1 to ip-10-1-12-138.eu-west-3.compute.internal
20m         Normal    SuccessfulAttachVolume         pod/consul-server-1                        AttachVolume.Attach succeeded for volume "pvc-ce67bb9b-cc8d-472d-86bd-dfaa97683633"
20m         Normal    Pulled                         pod/consul-server-1                        Container image "hub.simloudcorp.customers.simloud.com/hashicorp/consul:1.10.0" already present on machine
20m         Normal    Created                        pod/consul-server-1                        Created container consul
20m         Normal    Started                        pod/consul-server-1                        Started container consul
19m         Warning   Unhealthy                      pod/consul-server-1                        Readiness probe failed:
14m         Normal    ScaleDown                      pod/consul-server-1                        deleting pod for node scale down
14m         Normal    Killing                        pod/consul-server-1                        Stopping container consul
14m         Normal    Scheduled                      pod/consul-server-1                        Successfully assigned kube-system/consul-server-1 to ip-10-1-0-97.eu-west-3.compute.internal
14m         Normal    SuccessfulAttachVolume         pod/consul-server-1                        AttachVolume.Attach succeeded for volume "pvc-ce67bb9b-cc8d-472d-86bd-dfaa97683633"
14m         Normal    Pulled                         pod/consul-server-1                        Container image "hub.simloudcorp.customers.simloud.com/hashicorp/consul:1.10.0" already present on machine
14m         Normal    Created                        pod/consul-server-1                        Created container consul
13m         Normal    Started                        pod/consul-server-1                        Started container consul
12m         Warning   Unhealthy                      pod/consul-server-1                        Readiness probe failed:
56m         Normal    ScaleDown                      pod/consul-server-2                        deleting pod for node scale down
56m         Normal    Killing                        pod/consul-server-2                        Stopping container consul
56m         Normal    Scheduled                      pod/consul-server-2                        Successfully assigned kube-system/consul-server-2 to ip-10-1-55-135.eu-west-3.compute.internal
56m         Warning   FailedAttachVolume             pod/consul-server-2                        Multi-Attach error for volume "pvc-65217579-d248-43aa-b470-ddc811210e86" Volume is already exclusively attached to one node and can't be attached to another
56m         Normal    SuccessfulAttachVolume         pod/consul-server-2                        AttachVolume.Attach succeeded for volume "pvc-65217579-d248-43aa-b470-ddc811210e86"
55m         Normal    Pulled                         pod/consul-server-2                        Container image "hub.simloudcorp.customers.simloud.com/hashicorp/consul:1.10.0" already present on machine
55m         Normal    Created                        pod/consul-server-2                        Created container consul
55m         Normal    Started                        pod/consul-server-2                        Started container consul
29m         Normal    Killing                        pod/consul-server-2                        Stopping container consul
20m         Normal    Scheduled                      pod/consul-server-2                        Successfully assigned kube-system/consul-server-2 to ip-10-1-51-246.eu-west-3.compute.internal
20m         Normal    SuccessfulAttachVolume         pod/consul-server-2                        AttachVolume.Attach succeeded for volume "pvc-65217579-d248-43aa-b470-ddc811210e86"
20m         Normal    Pulled                         pod/consul-server-2                        Container image "hub.simloudcorp.customers.simloud.com/hashicorp/consul:1.10.0" already present on machine
20m         Normal    Created                        pod/consul-server-2                        Created container consul
20m         Normal    Started                        pod/consul-server-2                        Started container consul
12m         Warning   Unhealthy                      pod/consul-server-2                        Readiness probe failed:
29m         Normal    NoPods                         poddisruptionbudget/consul-server          No matching pods found
20m         Normal    SuccessfulCreate               statefulset/consul-server                  create Pod consul-server-0 in StatefulSet consul-server successful
14m         Normal    SuccessfulCreate               statefulset/consul-server                  create Pod consul-server-1 in StatefulSet consul-server successful
20m         Normal    SuccessfulCreate               statefulset/consul-server                  create Pod consul-server-2 in StatefulSet consul-server successful
29m         Normal    SuccessfulDelete               statefulset/consul-server                  delete Pod consul-server-2 in StatefulSet consul-server successful
29m         Normal    SuccessfulDelete               statefulset/consul-server                  delete Pod consul-server-1 in StatefulSet consul-server successful
29m         Normal    SuccessfulDelete               statefulset/consul-server                  delete Pod consul-server-0 in StatefulSet consul-server successful
56m         Warning   FailedToUpdateEndpoint         endpoints/consul-server                    Failed to update endpoint kube-system/consul-server: Operation cannot be fulfilled on endpoints "consul-server": the object has been modified; please apply your changes to the latest version and try again
53m         Warning   FailedToUpdateEndpointSlices   service/consul-server                      Error updating Endpoint Slices for Service kube-system/consul-server: node "ip-10-1-30-25.eu-west-3.compute.internal" not found
20m         Normal    Scheduled                      pod/consul-tmmx8                           Successfully assigned kube-system/consul-tmmx8 to ip-10-1-62-180.eu-west-3.compute.internal
20m         Normal    Pulling                        pod/consul-tmmx8                           Pulling image "hub.simloudcorp.customers.simloud.com/hashicorp/consul:1.10.0"
20m         Normal    Pulled                         pod/consul-tmmx8                           Successfully pulled image "hub.simloudcorp.customers.simloud.com/hashicorp/consul:1.10.0" in 11.941393222s
20m         Normal    Created                        pod/consul-tmmx8                           Created container consul
20m         Normal    Started                        pod/consul-tmmx8                           Started container consul
12m         Warning   Unhealthy                      pod/consul-tmmx8                           Readiness probe failed:
29m         Warning   Unhealthy                      pod/consul-xlwxd                           Readiness probe failed:
29m         Normal    Killing                        pod/consul-xlwxd                           Stopping container consul
37m         Normal    Scheduled                      pod/consul-zp86l                           Successfully assigned kube-system/consul-zp86l to ip-10-1-38-3.eu-west-3.compute.internal
37m         Normal    Pulling                        pod/consul-zp86l                           Pulling image "hub.simloudcorp.customers.simloud.com/hashicorp/consul:1.10.0"
37m         Normal    Pulled                         pod/consul-zp86l                           Successfully pulled image "hub.simloudcorp.customers.simloud.com/hashicorp/consul:1.10.0" in 6.751347012s
37m         Normal    Created                        pod/consul-zp86l                           Created container consul
37m         Normal    Started                        pod/consul-zp86l                           Started container consul
37m         Warning   Unhealthy                      pod/consul-zp86l                           Readiness probe failed:
29m         Normal    Killing                        pod/consul-zp86l                           Stopping container consul
29m         Warning   Unhealthy                      pod/consul-zp86l                           Readiness probe errored: rpc error: code = Unknown desc = Error: No such container: bbb4edd664ca1fa00f8605917b926d55cd757f3c9d27cc55d5eb10a7ae937f98
56m         Warning   FailedToUpdateEndpoint         endpoints/consul                           Failed to update endpoint kube-system/consul: Operation cannot be fulfilled on endpoints "consul": the object has been modified; please apply your changes to the latest version and try again
54m         Normal    SuccessfulCreate               daemonset/consul                           Created pod: consul-q7hwq
53m         Warning   FailedToUpdateEndpointSlices   service/consul                             Error updating Endpoint Slices for Service kube-system/consul: node "ip-10-1-30-25.eu-west-3.compute.internal" not found
47m         Normal    SuccessfulCreate               daemonset/consul                           Created pod: consul-b2pcs
37m         Normal    SuccessfulCreate               daemonset/consul                           Created pod: consul-zp86l
34m         Normal    SuccessfulCreate               daemonset/consul                           Created pod: consul-q7hcx
29m         Normal    SuccessfulDelete               daemonset/consul                           Deleted pod: consul-p5hvd
29m         Normal    SuccessfulDelete               daemonset/consul                           Deleted pod: consul-xlwxd
29m         Normal    SuccessfulDelete               daemonset/consul                           Deleted pod: consul-zp86l
29m         Normal    SuccessfulDelete               daemonset/consul                           Deleted pod: consul-4l5wn
29m         Normal    SuccessfulDelete               daemonset/consul                           Deleted pod: consul-q7hcx
20m         Normal    SuccessfulCreate               daemonset/consul                           Created pod: consul-56fn4
20m         Normal    SuccessfulCreate               daemonset/consul                           Created pod: consul-ld6vw
20m         Normal    SuccessfulCreate               daemonset/consul                           Created pod: consul-qtx76
20m         Normal    SuccessfulCreate               daemonset/consul                           Created pod: consul-tmmx8
20m         Normal    SuccessfulCreate               daemonset/consul                           Created pod: consul-qrqvn
12m         Normal    SuccessfulCreate               daemonset/consul                           Created pod: consul-2bckm
29m         Normal    Killing                        pod/coredns-9b5d74bfb-24fcd                Stopping container coredns
28m         Warning   FailedScheduling               pod/coredns-9b5d74bfb-2gdfw                0/5 nodes are available: 5 node(s) were unschedulable.
28m         Warning   FailedScheduling               pod/coredns-9b5d74bfb-2gdfw                0/3 nodes are available: 3 node(s) were unschedulable.
21m         Warning   FailedScheduling               pod/coredns-9b5d74bfb-2gdfw                no nodes available to schedule pods
21m         Warning   FailedScheduling               pod/coredns-9b5d74bfb-2gdfw                0/3 nodes are available: 3 node(s) had taint {node.kubernetes.io/not-ready: }, that the pod didn't tolerate.
21m         Warning   FailedScheduling               pod/coredns-9b5d74bfb-2gdfw                0/5 nodes are available: 5 node(s) had taint {node.kubernetes.io/not-ready: }, that the pod didn't tolerate.
20m         Normal    Scheduled                      pod/coredns-9b5d74bfb-2gdfw                Successfully assigned kube-system/coredns-9b5d74bfb-2gdfw to ip-10-1-37-225.eu-west-3.compute.internal
20m         Normal    Pulling                        pod/coredns-9b5d74bfb-2gdfw                Pulling image "602401143452.dkr.ecr.eu-west-3.amazonaws.com/eks/coredns:v1.8.4-eksbuild.1"
20m         Normal    Pulled                         pod/coredns-9b5d74bfb-2gdfw                Successfully pulled image "602401143452.dkr.ecr.eu-west-3.amazonaws.com/eks/coredns:v1.8.4-eksbuild.1" in 1.134590902s
20m         Normal    Created                        pod/coredns-9b5d74bfb-2gdfw                Created container coredns
20m         Normal    Started                        pod/coredns-9b5d74bfb-2gdfw                Started container coredns
12m         Warning   NodeNotReady                   pod/coredns-9b5d74bfb-2gdfw                Node is not ready
11m         Normal    TaintManagerEviction           pod/coredns-9b5d74bfb-2gdfw                Cancelling deletion of Pod kube-system/coredns-9b5d74bfb-2gdfw
28m         Warning   FailedScheduling               pod/coredns-9b5d74bfb-4dkhb                0/5 nodes are available: 5 node(s) were unschedulable.
28m         Warning   FailedScheduling               pod/coredns-9b5d74bfb-4dkhb                0/4 nodes are available: 4 node(s) were unschedulable.
21m         Warning   FailedScheduling               pod/coredns-9b5d74bfb-4dkhb                no nodes available to schedule pods
21m         Warning   FailedScheduling               pod/coredns-9b5d74bfb-4dkhb                0/3 nodes are available: 3 node(s) had taint {node.kubernetes.io/not-ready: }, that the pod didn't tolerate.
21m         Warning   FailedScheduling               pod/coredns-9b5d74bfb-4dkhb                0/5 nodes are available: 5 node(s) had taint {node.kubernetes.io/not-ready: }, that the pod didn't tolerate.
20m         Normal    Scheduled                      pod/coredns-9b5d74bfb-4dkhb                Successfully assigned kube-system/coredns-9b5d74bfb-4dkhb to ip-10-1-0-97.eu-west-3.compute.internal
20m         Normal    Pulling                        pod/coredns-9b5d74bfb-4dkhb                Pulling image "602401143452.dkr.ecr.eu-west-3.amazonaws.com/eks/coredns:v1.8.4-eksbuild.1"
20m         Normal    Pulled                         pod/coredns-9b5d74bfb-4dkhb                Successfully pulled image "602401143452.dkr.ecr.eu-west-3.amazonaws.com/eks/coredns:v1.8.4-eksbuild.1" in 1.202991017s
20m         Normal    Created                        pod/coredns-9b5d74bfb-4dkhb                Created container coredns
20m         Normal    Started                        pod/coredns-9b5d74bfb-4dkhb                Started container coredns
11m         Normal    Scheduled                      pod/coredns-9b5d74bfb-dsmk2                Successfully assigned kube-system/coredns-9b5d74bfb-dsmk2 to ip-10-1-26-106.eu-west-3.compute.internal
11m         Normal    Pulling                        pod/coredns-9b5d74bfb-dsmk2                Pulling image "602401143452.dkr.ecr.eu-west-3.amazonaws.com/eks/coredns:v1.8.4-eksbuild.1"
11m         Normal    Pulled                         pod/coredns-9b5d74bfb-dsmk2                Successfully pulled image "602401143452.dkr.ecr.eu-west-3.amazonaws.com/eks/coredns:v1.8.4-eksbuild.1" in 1.372818228s
11m         Normal    Created                        pod/coredns-9b5d74bfb-dsmk2                Created container coredns
11m         Normal    Started                        pod/coredns-9b5d74bfb-dsmk2                Started container coredns
56m         Normal    ScaleDown                      pod/coredns-9b5d74bfb-x6mgf                deleting pod for node scale down
56m         Normal    Killing                        pod/coredns-9b5d74bfb-x6mgf                Stopping container coredns
56m         Normal    Scheduled                      pod/coredns-9b5d74bfb-z6hhx                Successfully assigned kube-system/coredns-9b5d74bfb-z6hhx to ip-10-1-9-246.eu-west-3.compute.internal
56m         Normal    Pulling                        pod/coredns-9b5d74bfb-z6hhx                Pulling image "602401143452.dkr.ecr.eu-west-3.amazonaws.com/eks/coredns:v1.8.4-eksbuild.1"
56m         Normal    Pulled                         pod/coredns-9b5d74bfb-z6hhx                Successfully pulled image "602401143452.dkr.ecr.eu-west-3.amazonaws.com/eks/coredns:v1.8.4-eksbuild.1" in 1.484716294s
56m         Normal    Created                        pod/coredns-9b5d74bfb-z6hhx                Created container coredns
56m         Normal    Started                        pod/coredns-9b5d74bfb-z6hhx                Started container coredns
29m         Normal    Killing                        pod/coredns-9b5d74bfb-z6hhx                Stopping container coredns
29m         Warning   Unhealthy                      pod/coredns-9b5d74bfb-z6hhx                Readiness probe failed: Get "http://10.1.29.7:8080/health": context deadline exceeded (Client.Timeout exceeded while awaiting headers)
29m         Warning   Unhealthy                      pod/coredns-9b5d74bfb-z6hhx                Liveness probe failed: Get "http://10.1.29.7:8080/health": context deadline exceeded (Client.Timeout exceeded while awaiting headers)
56m         Normal    SuccessfulCreate               replicaset/coredns-9b5d74bfb               Created pod: coredns-9b5d74bfb-z6hhx
29m         Normal    SuccessfulCreate               replicaset/coredns-9b5d74bfb               Created pod: coredns-9b5d74bfb-2gdfw
29m         Normal    SuccessfulCreate               replicaset/coredns-9b5d74bfb               Created pod: coredns-9b5d74bfb-4dkhb
11m         Normal    SuccessfulCreate               replicaset/coredns-9b5d74bfb               Created pod: coredns-9b5d74bfb-dsmk2
20m         Normal    Scheduled                      pod/dashboard-7f7d79fd8b-5pzrx             Successfully assigned kube-system/dashboard-7f7d79fd8b-5pzrx to ip-10-1-37-225.eu-west-3.compute.internal
20m         Normal    Pulling                        pod/dashboard-7f7d79fd8b-5pzrx             Pulling image "hub.simloudcorp.customers.simloud.com/kubernetesui/dashboard:v2.0.4"
20m         Normal    Pulled                         pod/dashboard-7f7d79fd8b-5pzrx             Successfully pulled image "hub.simloudcorp.customers.simloud.com/kubernetesui/dashboard:v2.0.4" in 15.403761737s
20m         Normal    Created                        pod/dashboard-7f7d79fd8b-5pzrx             Created container dashboard
20m         Normal    Started                        pod/dashboard-7f7d79fd8b-5pzrx             Started container dashboard
20m         Normal    Pulling                        pod/dashboard-7f7d79fd8b-5pzrx             Pulling image "hub.simloudcorp.customers.simloud.com/kubernetesui/metrics-scraper:v1.0.4"
19m         Normal    Pulled                         pod/dashboard-7f7d79fd8b-5pzrx             Successfully pulled image "hub.simloudcorp.customers.simloud.com/kubernetesui/metrics-scraper:v1.0.4" in 3.314378472s
19m         Normal    Created                        pod/dashboard-7f7d79fd8b-5pzrx             Created container dashboard-metrics-scraper
19m         Normal    Started                        pod/dashboard-7f7d79fd8b-5pzrx             Started container dashboard-metrics-scraper
12m         Warning   NodeNotReady                   pod/dashboard-7f7d79fd8b-5pzrx             Node is not ready
11m         Normal    TaintManagerEviction           pod/dashboard-7f7d79fd8b-5pzrx             Cancelling deletion of Pod kube-system/dashboard-7f7d79fd8b-5pzrx
11m         Normal    Scheduled                      pod/dashboard-7f7d79fd8b-82tc9             Successfully assigned kube-system/dashboard-7f7d79fd8b-82tc9 to ip-10-1-26-106.eu-west-3.compute.internal
11m         Normal    Pulling                        pod/dashboard-7f7d79fd8b-82tc9             Pulling image "hub.simloudcorp.customers.simloud.com/kubernetesui/dashboard:v2.0.4"
11m         Normal    Pulled                         pod/dashboard-7f7d79fd8b-82tc9             Successfully pulled image "hub.simloudcorp.customers.simloud.com/kubernetesui/dashboard:v2.0.4" in 9.998643645s
11m         Normal    Created                        pod/dashboard-7f7d79fd8b-82tc9             Created container dashboard
11m         Normal    Started                        pod/dashboard-7f7d79fd8b-82tc9             Started container dashboard
11m         Normal    Pulling                        pod/dashboard-7f7d79fd8b-82tc9             Pulling image "hub.simloudcorp.customers.simloud.com/kubernetesui/metrics-scraper:v1.0.4"
11m         Normal    Pulled                         pod/dashboard-7f7d79fd8b-82tc9             Successfully pulled image "hub.simloudcorp.customers.simloud.com/kubernetesui/metrics-scraper:v1.0.4" in 2.508188772s
11m         Normal    Created                        pod/dashboard-7f7d79fd8b-82tc9             Created container dashboard-metrics-scraper
11m         Normal    Started                        pod/dashboard-7f7d79fd8b-82tc9             Started container dashboard-metrics-scraper
29m         Normal    Killing                        pod/dashboard-7f7d79fd8b-thcx9             Stopping container dashboard
29m         Normal    Killing                        pod/dashboard-7f7d79fd8b-thcx9             Stopping container dashboard-metrics-scraper
29m         Normal    SuccessfulDelete               replicaset/dashboard-7f7d79fd8b            Deleted pod: dashboard-7f7d79fd8b-thcx9
20m         Normal    SuccessfulCreate               replicaset/dashboard-7f7d79fd8b            Created pod: dashboard-7f7d79fd8b-5pzrx
11m         Normal    SuccessfulCreate               replicaset/dashboard-7f7d79fd8b            Created pod: dashboard-7f7d79fd8b-82tc9
20m         Normal    ScalingReplicaSet              deployment/dashboard                       Scaled up replica set dashboard-7f7d79fd8b to 1
29m         Normal    ScalingReplicaSet              deployment/dashboard                       Scaled down replica set dashboard-7f7d79fd8b to 0
54m         Normal    CREATE                         ingress/dashboard                          Ingress kube-system/dashboard
47m         Normal    CREATE                         ingress/dashboard                          Ingress kube-system/dashboard
37m         Normal    CREATE                         ingress/dashboard                          Ingress kube-system/dashboard
34m         Normal    CREATE                         ingress/dashboard                          Ingress kube-system/dashboard
20m         Normal    CREATE                         ingress/dashboard                          Ingress kube-system/dashboard
20m         Normal    CREATE                         ingress/dashboard                          Ingress kube-system/dashboard
19m         Normal    CREATE                         ingress/dashboard                          Ingress kube-system/dashboard
19m         Normal    CREATE                         ingress/dashboard                          Ingress kube-system/dashboard
19m         Normal    CREATE                         ingress/dashboard                          Ingress kube-system/dashboard
19m         Normal    UPDATE                         ingress/dashboard                          Ingress kube-system/dashboard
19m         Normal    UPDATE                         ingress/dashboard                          Ingress kube-system/dashboard
19m         Normal    UPDATE                         ingress/dashboard                          Ingress kube-system/dashboard
19m         Normal    UPDATE                         ingress/dashboard                          Ingress kube-system/dashboard
19m         Normal    UPDATE                         ingress/dashboard                          Ingress kube-system/dashboard
11m         Normal    CREATE                         ingress/dashboard                          Ingress kube-system/dashboard
14m         Normal    Scheduled                      pod/grafana-b488bf7c-69ddg                 Successfully assigned kube-system/grafana-b488bf7c-69ddg to ip-10-1-0-97.eu-west-3.compute.internal
14m         Warning   FailedAttachVolume             pod/grafana-b488bf7c-69ddg                 Multi-Attach error for volume "pvc-c6811d25-441e-4b55-9f92-3bc75aeb74f2" Volume is already used by pod(s) grafana-b488bf7c-84nwq
14m         Warning   FailedMount                    pod/grafana-b488bf7c-69ddg                 MountVolume.SetUp failed for volume "dashboards-nlb" : failed to sync configmap cache: timed out waiting for the condition
14m         Normal    SuccessfulAttachVolume         pod/grafana-b488bf7c-69ddg                 AttachVolume.Attach succeeded for volume "pvc-c6811d25-441e-4b55-9f92-3bc75aeb74f2"
13m         Normal    Pulling                        pod/grafana-b488bf7c-69ddg                 Pulling image "hub.simloudcorp.customers.simloud.com/simloud/busybox/busybox:1.31.1"
13m         Normal    Pulled                         pod/grafana-b488bf7c-69ddg                 Successfully pulled image "hub.simloudcorp.customers.simloud.com/simloud/busybox/busybox:1.31.1" in 697.661588ms
13m         Normal    Created                        pod/grafana-b488bf7c-69ddg                 Created container init-chown-data
13m         Normal    Started                        pod/grafana-b488bf7c-69ddg                 Started container init-chown-data
13m         Normal    Pulling                        pod/grafana-b488bf7c-69ddg                 Pulling image "hub.simloudcorp.customers.simloud.com/curlimages/curl:7.70.0"
13m         Normal    Pulled                         pod/grafana-b488bf7c-69ddg                 Successfully pulled image "hub.simloudcorp.customers.simloud.com/curlimages/curl:7.70.0" in 1.882645134s
13m         Normal    Created                        pod/grafana-b488bf7c-69ddg                 Created container download-dashboards
13m         Normal    Started                        pod/grafana-b488bf7c-69ddg                 Started container download-dashboards
13m         Normal    Pulling                        pod/grafana-b488bf7c-69ddg                 Pulling image "hub.simloudcorp.customers.simloud.com/grafana/grafana:7.2.0"
13m         Normal    Pulled                         pod/grafana-b488bf7c-69ddg                 Successfully pulled image "hub.simloudcorp.customers.simloud.com/grafana/grafana:7.2.0" in 4.977390101s
13m         Normal    Created                        pod/grafana-b488bf7c-69ddg                 Created container grafana
13m         Normal    Started                        pod/grafana-b488bf7c-69ddg                 Started container grafana
13m         Warning   Unhealthy                      pod/grafana-b488bf7c-69ddg                 Readiness probe failed: Get "http://10.1.25.29:3000/api/health": dial tcp 10.1.25.29:3000: connect: connection refused
20m         Normal    Scheduled                      pod/grafana-b488bf7c-84nwq                 Successfully assigned kube-system/grafana-b488bf7c-84nwq to ip-10-1-12-138.eu-west-3.compute.internal
20m         Warning   FailedMount                    pod/grafana-b488bf7c-84nwq                 MountVolume.SetUp failed for volume "dashboards-ebs" : failed to sync configmap cache: timed out waiting for the condition
20m         Warning   FailedMount                    pod/grafana-b488bf7c-84nwq                 MountVolume.SetUp failed for volume "dashboards-s3" : failed to sync configmap cache: timed out waiting for the condition
20m         Warning   FailedMount                    pod/grafana-b488bf7c-84nwq                 MountVolume.SetUp failed for volume "dashboards-default" : failed to sync configmap cache: timed out waiting for the condition
20m         Warning   FailedMount                    pod/grafana-b488bf7c-84nwq                 MountVolume.SetUp failed for volume "dashboards-apigw" : failed to sync configmap cache: timed out waiting for the condition
20m         Warning   FailedMount                    pod/grafana-b488bf7c-84nwq                 MountVolume.SetUp failed for volume "dashboards-r53" : failed to sync configmap cache: timed out waiting for the condition
20m         Warning   FailedMount                    pod/grafana-b488bf7c-84nwq                 MountVolume.SetUp failed for volume "dashboards-logs" : failed to sync configmap cache: timed out waiting for the condition
20m         Normal    SuccessfulAttachVolume         pod/grafana-b488bf7c-84nwq                 AttachVolume.Attach succeeded for volume "pvc-c6811d25-441e-4b55-9f92-3bc75aeb74f2"
19m         Normal    Pulling                        pod/grafana-b488bf7c-84nwq                 Pulling image "hub.simloudcorp.customers.simloud.com/simloud/busybox/busybox:1.31.1"
19m         Normal    Pulled                         pod/grafana-b488bf7c-84nwq                 Successfully pulled image "hub.simloudcorp.customers.simloud.com/simloud/busybox/busybox:1.31.1" in 1.058995226s
19m         Normal    Created                        pod/grafana-b488bf7c-84nwq                 Created container init-chown-data
19m         Normal    Started                        pod/grafana-b488bf7c-84nwq                 Started container init-chown-data
19m         Normal    Pulling                        pod/grafana-b488bf7c-84nwq                 Pulling image "hub.simloudcorp.customers.simloud.com/curlimages/curl:7.70.0"
19m         Normal    Pulled                         pod/grafana-b488bf7c-84nwq                 Successfully pulled image "hub.simloudcorp.customers.simloud.com/curlimages/curl:7.70.0" in 2.060613842s
19m         Normal    Created                        pod/grafana-b488bf7c-84nwq                 Created container download-dashboards
19m         Normal    Started                        pod/grafana-b488bf7c-84nwq                 Started container download-dashboards
19m         Normal    Pulling                        pod/grafana-b488bf7c-84nwq                 Pulling image "hub.simloudcorp.customers.simloud.com/grafana/grafana:7.2.0"
19m         Normal    Pulled                         pod/grafana-b488bf7c-84nwq                 Successfully pulled image "hub.simloudcorp.customers.simloud.com/grafana/grafana:7.2.0" in 5.647530823s
19m         Normal    Created                        pod/grafana-b488bf7c-84nwq                 Created container grafana
19m         Normal    Started                        pod/grafana-b488bf7c-84nwq                 Started container grafana
14m         Normal    ScaleDown                      pod/grafana-b488bf7c-84nwq                 deleting pod for node scale down
14m         Normal    Killing                        pod/grafana-b488bf7c-84nwq                 Stopping container grafana
53m         Normal    Scheduled                      pod/grafana-b488bf7c-nkwt2                 Successfully assigned kube-system/grafana-b488bf7c-nkwt2 to ip-10-1-9-246.eu-west-3.compute.internal
53m         Warning   FailedMount                    pod/grafana-b488bf7c-nkwt2                 MountVolume.SetUp failed for volume "dashboards-cf" : failed to sync configmap cache: timed out waiting for the condition
53m         Warning   FailedMount                    pod/grafana-b488bf7c-nkwt2                 MountVolume.SetUp failed for volume "dashboards-ebs" : failed to sync configmap cache: timed out waiting for the condition
53m         Warning   FailedMount                    pod/grafana-b488bf7c-nkwt2                 MountVolume.SetUp failed for volume "dashboards-rds" : failed to sync configmap cache: timed out waiting for the condition
53m         Warning   FailedMount                    pod/grafana-b488bf7c-nkwt2                 MountVolume.SetUp failed for volume "dashboards-bill" : failed to sync configmap cache: timed out waiting for the condition
53m         Normal    SuccessfulAttachVolume         pod/grafana-b488bf7c-nkwt2                 AttachVolume.Attach succeeded for volume "pvc-c6811d25-441e-4b55-9f92-3bc75aeb74f2"
53m         Normal    Pulling                        pod/grafana-b488bf7c-nkwt2                 Pulling image "hub.simloudcorp.customers.simloud.com/simloud/busybox/busybox:1.31.1"
53m         Normal    Pulled                         pod/grafana-b488bf7c-nkwt2                 Successfully pulled image "hub.simloudcorp.customers.simloud.com/simloud/busybox/busybox:1.31.1" in 707.429613ms
53m         Normal    Created                        pod/grafana-b488bf7c-nkwt2                 Created container init-chown-data
53m         Normal    Started                        pod/grafana-b488bf7c-nkwt2                 Started container init-chown-data
53m         Normal    Pulling                        pod/grafana-b488bf7c-nkwt2                 Pulling image "hub.simloudcorp.customers.simloud.com/curlimages/curl:7.70.0"
53m         Normal    Pulled                         pod/grafana-b488bf7c-nkwt2                 Successfully pulled image "hub.simloudcorp.customers.simloud.com/curlimages/curl:7.70.0" in 2.359981136s
53m         Normal    Created                        pod/grafana-b488bf7c-nkwt2                 Created container download-dashboards
53m         Normal    Started                        pod/grafana-b488bf7c-nkwt2                 Started container download-dashboards
53m         Normal    Pulling                        pod/grafana-b488bf7c-nkwt2                 Pulling image "hub.simloudcorp.customers.simloud.com/grafana/grafana:7.2.0"
53m         Normal    Pulled                         pod/grafana-b488bf7c-nkwt2                 Successfully pulled image "hub.simloudcorp.customers.simloud.com/grafana/grafana:7.2.0" in 5.699704329s
53m         Normal    Created                        pod/grafana-b488bf7c-nkwt2                 Created container grafana
53m         Normal    Started                        pod/grafana-b488bf7c-nkwt2                 Started container grafana
29m         Normal    Killing                        pod/grafana-b488bf7c-nkwt2                 Stopping container grafana
55m         Warning   NodeNotReady                   pod/grafana-b488bf7c-rxltj                 Node is not ready
53m         Warning   FailedAttachVolume             pod/grafana-b488bf7c-rxltj                 AttachVolume.Attach failed for volume "pvc-c6811d25-441e-4b55-9f92-3bc75aeb74f2" : error finding instance ip-10-1-30-25.eu-west-3.compute.internal: "instance not found"
53m         Normal    TaintManagerEviction           pod/grafana-b488bf7c-rxltj                 Cancelling deletion of Pod kube-system/grafana-b488bf7c-rxltj
53m         Normal    SuccessfulCreate               replicaset/grafana-b488bf7c                Created pod: grafana-b488bf7c-nkwt2
29m         Normal    SuccessfulDelete               replicaset/grafana-b488bf7c                Deleted pod: grafana-b488bf7c-nkwt2
20m         Normal    SuccessfulCreate               replicaset/grafana-b488bf7c                Created pod: grafana-b488bf7c-84nwq
14m         Normal    SuccessfulCreate               replicaset/grafana-b488bf7c                Created pod: grafana-b488bf7c-69ddg
20m         Normal    ScalingReplicaSet              deployment/grafana                         Scaled up replica set grafana-b488bf7c to 1
29m         Normal    ScalingReplicaSet              deployment/grafana                         Scaled down replica set grafana-b488bf7c to 0
54m         Normal    CREATE                         ingress/grafana                            Ingress kube-system/grafana
47m         Normal    CREATE                         ingress/grafana                            Ingress kube-system/grafana
37m         Normal    CREATE                         ingress/grafana                            Ingress kube-system/grafana
34m         Normal    CREATE                         ingress/grafana                            Ingress kube-system/grafana
20m         Normal    CREATE                         ingress/grafana                            Ingress kube-system/grafana
20m         Normal    CREATE                         ingress/grafana                            Ingress kube-system/grafana
19m         Normal    CREATE                         ingress/grafana                            Ingress kube-system/grafana
19m         Normal    CREATE                         ingress/grafana                            Ingress kube-system/grafana
19m         Normal    CREATE                         ingress/grafana                            Ingress kube-system/grafana
19m         Normal    UPDATE                         ingress/grafana                            Ingress kube-system/grafana
19m         Normal    UPDATE                         ingress/grafana                            Ingress kube-system/grafana
19m         Normal    UPDATE                         ingress/grafana                            Ingress kube-system/grafana
19m         Normal    UPDATE                         ingress/grafana                            Ingress kube-system/grafana
19m         Normal    UPDATE                         ingress/grafana                            Ingress kube-system/grafana
11m         Normal    CREATE                         ingress/grafana                            Ingress kube-system/grafana
11m         Warning   FailedToUpdateEndpoint         endpoints/kube-dns                         Failed to update endpoint kube-system/kube-dns: Operation cannot be fulfilled on endpoints "kube-dns": the object has been modified; please apply your changes to the latest version and try again
12m         Normal    Scheduled                      pod/kube-proxy-2jlbc                       Successfully assigned kube-system/kube-proxy-2jlbc to ip-10-1-26-106.eu-west-3.compute.internal
12m         Normal    Pulling                        pod/kube-proxy-2jlbc                       Pulling image "602401143452.dkr.ecr.eu-west-3.amazonaws.com/eks/kube-proxy:v1.21.2-eksbuild.2"
12m         Normal    Pulled                         pod/kube-proxy-2jlbc                       Successfully pulled image "602401143452.dkr.ecr.eu-west-3.amazonaws.com/eks/kube-proxy:v1.21.2-eksbuild.2" in 5.864831402s
12m         Normal    Created                        pod/kube-proxy-2jlbc                       Created container kube-proxy
12m         Normal    Started                        pod/kube-proxy-2jlbc                       Started container kube-proxy
21m         Normal    Scheduled                      pod/kube-proxy-6nqhz                       Successfully assigned kube-system/kube-proxy-6nqhz to ip-10-1-62-180.eu-west-3.compute.internal
21m         Normal    Pulling                        pod/kube-proxy-6nqhz                       Pulling image "602401143452.dkr.ecr.eu-west-3.amazonaws.com/eks/kube-proxy:v1.21.2-eksbuild.2"
21m         Normal    Pulled                         pod/kube-proxy-6nqhz                       Successfully pulled image "602401143452.dkr.ecr.eu-west-3.amazonaws.com/eks/kube-proxy:v1.21.2-eksbuild.2" in 5.700981512s
21m         Normal    Created                        pod/kube-proxy-6nqhz                       Created container kube-proxy
21m         Normal    Started                        pod/kube-proxy-6nqhz                       Started container kube-proxy
48m         Normal    Scheduled                      pod/kube-proxy-6nqq8                       Successfully assigned kube-system/kube-proxy-6nqq8 to ip-10-1-1-25.eu-west-3.compute.internal
48m         Normal    Pulling                        pod/kube-proxy-6nqq8                       Pulling image "602401143452.dkr.ecr.eu-west-3.amazonaws.com/eks/kube-proxy:v1.21.2-eksbuild.2"
48m         Normal    Pulled                         pod/kube-proxy-6nqq8                       Successfully pulled image "602401143452.dkr.ecr.eu-west-3.amazonaws.com/eks/kube-proxy:v1.21.2-eksbuild.2" in 5.516748484s
48m         Normal    Created                        pod/kube-proxy-6nqq8                       Created container kube-proxy
48m         Normal    Started                        pod/kube-proxy-6nqq8                       Started container kube-proxy
38m         Warning   NodeNotReady                   pod/kube-proxy-6nqq8                       Node is not ready
56m         Normal    ScaleDown                      pod/kube-proxy-cnq24                       deleting pod for node scale down
56m         Normal    Killing                        pod/kube-proxy-cnq24                       Stopping container kube-proxy
40m         Normal    Scheduled                      pod/kube-proxy-fnscv                       Successfully assigned kube-system/kube-proxy-fnscv to ip-10-1-52-192.eu-west-3.compute.internal
39m         Normal    Pulled                         pod/kube-proxy-fnscv                       Container image "602401143452.dkr.ecr.eu-west-3.amazonaws.com/eks/kube-proxy:v1.21.2-eksbuild.2" already present on machine
39m         Normal    Created                        pod/kube-proxy-fnscv                       Created container kube-proxy
39m         Normal    Started                        pod/kube-proxy-fnscv                       Started container kube-proxy
38m         Warning   NodeNotReady                   pod/kube-proxy-fnscv                       Node is not ready
28m         Warning   NodeNotReady                   pod/kube-proxy-grxjd                       Node is not ready
21m         Normal    Scheduled                      pod/kube-proxy-hslqr                       Successfully assigned kube-system/kube-proxy-hslqr to ip-10-1-51-246.eu-west-3.compute.internal
21m         Normal    Pulling                        pod/kube-proxy-hslqr                       Pulling image "602401143452.dkr.ecr.eu-west-3.amazonaws.com/eks/kube-proxy:v1.21.2-eksbuild.2"
21m         Normal    Pulled                         pod/kube-proxy-hslqr                       Successfully pulled image "602401143452.dkr.ecr.eu-west-3.amazonaws.com/eks/kube-proxy:v1.21.2-eksbuild.2" in 5.446427228s
21m         Normal    Created                        pod/kube-proxy-hslqr                       Created container kube-proxy
21m         Normal    Started                        pod/kube-proxy-hslqr                       Started container kube-proxy
28m         Warning   NodeNotReady                   pod/kube-proxy-p9n2z                       Node is not ready
21m         Normal    Scheduled                      pod/kube-proxy-q9nwx                       Successfully assigned kube-system/kube-proxy-q9nwx to ip-10-1-37-225.eu-west-3.compute.internal
21m         Normal    Pulling                        pod/kube-proxy-q9nwx                       Pulling image "602401143452.dkr.ecr.eu-west-3.amazonaws.com/eks/kube-proxy:v1.21.2-eksbuild.2"
21m         Normal    Pulled                         pod/kube-proxy-q9nwx                       Successfully pulled image "602401143452.dkr.ecr.eu-west-3.amazonaws.com/eks/kube-proxy:v1.21.2-eksbuild.2" in 5.497762291s
21m         Normal    Created                        pod/kube-proxy-q9nwx                       Created container kube-proxy
21m         Normal    Started                        pod/kube-proxy-q9nwx                       Started container kube-proxy
12m         Warning   NodeNotReady                   pod/kube-proxy-q9nwx                       Node is not ready
35m         Normal    Scheduled                      pod/kube-proxy-qsj4w                       Successfully assigned kube-system/kube-proxy-qsj4w to ip-10-1-32-108.eu-west-3.compute.internal
34m         Normal    Pulling                        pod/kube-proxy-qsj4w                       Pulling image "602401143452.dkr.ecr.eu-west-3.amazonaws.com/eks/kube-proxy:v1.21.2-eksbuild.2"
34m         Normal    Pulled                         pod/kube-proxy-qsj4w                       Successfully pulled image "602401143452.dkr.ecr.eu-west-3.amazonaws.com/eks/kube-proxy:v1.21.2-eksbuild.2" in 5.547603385s
34m         Normal    Created                        pod/kube-proxy-qsj4w                       Created container kube-proxy
34m         Normal    Started                        pod/kube-proxy-qsj4w                       Started container kube-proxy
28m         Warning   NodeNotReady                   pod/kube-proxy-qsj4w                       Node is not ready
55m         Warning   NodeNotReady                   pod/kube-proxy-r9vx6                       Node is not ready
21m         Normal    Scheduled                      pod/kube-proxy-rvm55                       Successfully assigned kube-system/kube-proxy-rvm55 to ip-10-1-0-97.eu-west-3.compute.internal
21m         Normal    Pulling                        pod/kube-proxy-rvm55                       Pulling image "602401143452.dkr.ecr.eu-west-3.amazonaws.com/eks/kube-proxy:v1.21.2-eksbuild.2"
21m         Normal    Pulled                         pod/kube-proxy-rvm55                       Successfully pulled image "602401143452.dkr.ecr.eu-west-3.amazonaws.com/eks/kube-proxy:v1.21.2-eksbuild.2" in 5.991084906s
21m         Normal    Created                        pod/kube-proxy-rvm55                       Created container kube-proxy
21m         Normal    Started                        pod/kube-proxy-rvm55                       Started container kube-proxy
28m         Warning   NodeNotReady                   pod/kube-proxy-sgjgb                       Node is not ready
38m         Normal    Scheduled                      pod/kube-proxy-v64xm                       Successfully assigned kube-system/kube-proxy-v64xm to ip-10-1-38-3.eu-west-3.compute.internal
38m         Normal    Pulling                        pod/kube-proxy-v64xm                       Pulling image "602401143452.dkr.ecr.eu-west-3.amazonaws.com/eks/kube-proxy:v1.21.2-eksbuild.2"
38m         Normal    Pulled                         pod/kube-proxy-v64xm                       Successfully pulled image "602401143452.dkr.ecr.eu-west-3.amazonaws.com/eks/kube-proxy:v1.21.2-eksbuild.2" in 5.860763489s
38m         Normal    Created                        pod/kube-proxy-v64xm                       Created container kube-proxy
38m         Normal    Started                        pod/kube-proxy-v64xm                       Started container kube-proxy
28m         Warning   NodeNotReady                   pod/kube-proxy-v64xm                       Node is not ready
14m         Normal    Scheduled                      pod/kube-proxy-v6vpk                       Successfully assigned kube-system/kube-proxy-v6vpk to ip-10-1-12-138.eu-west-3.compute.internal
14m         Normal    Pulled                         pod/kube-proxy-v6vpk                       Container image "602401143452.dkr.ecr.eu-west-3.amazonaws.com/eks/kube-proxy:v1.21.2-eksbuild.2" already present on machine
14m         Normal    Created                        pod/kube-proxy-v6vpk                       Created container kube-proxy
14m         Normal    Started                        pod/kube-proxy-v6vpk                       Started container kube-proxy
13m         Warning   NodeNotReady                   pod/kube-proxy-v6vpk                       Node is not ready
54m         Normal    Scheduled                      pod/kube-proxy-vwk72                       Successfully assigned kube-system/kube-proxy-vwk72 to ip-10-1-52-192.eu-west-3.compute.internal
54m         Normal    Pulling                        pod/kube-proxy-vwk72                       Pulling image "602401143452.dkr.ecr.eu-west-3.amazonaws.com/eks/kube-proxy:v1.21.2-eksbuild.2"
54m         Normal    Pulled                         pod/kube-proxy-vwk72                       Successfully pulled image "602401143452.dkr.ecr.eu-west-3.amazonaws.com/eks/kube-proxy:v1.21.2-eksbuild.2" in 5.791987389s
54m         Normal    Created                        pod/kube-proxy-vwk72                       Created container kube-proxy
54m         Normal    Started                        pod/kube-proxy-vwk72                       Started container kube-proxy
40m         Normal    ScaleDown                      pod/kube-proxy-vwk72                       deleting pod for node scale down
40m         Normal    Killing                        pod/kube-proxy-vwk72                       Stopping container kube-proxy
56m         Normal    Scheduled                      pod/kube-proxy-wj8dg                       Successfully assigned kube-system/kube-proxy-wj8dg to ip-10-1-34-180.eu-west-3.compute.internal
56m         Normal    Pulled                         pod/kube-proxy-wj8dg                       Container image "602401143452.dkr.ecr.eu-west-3.amazonaws.com/eks/kube-proxy:v1.21.2-eksbuild.2" already present on machine
56m         Normal    Created                        pod/kube-proxy-wj8dg                       Created container kube-proxy
56m         Normal    Started                        pod/kube-proxy-wj8dg                       Started container kube-proxy
55m         Warning   NodeNotReady                   pod/kube-proxy-wj8dg                       Node is not ready
21m         Normal    Scheduled                      pod/kube-proxy-zft5j                       Successfully assigned kube-system/kube-proxy-zft5j to ip-10-1-12-138.eu-west-3.compute.internal
21m         Normal    Pulling                        pod/kube-proxy-zft5j                       Pulling image "602401143452.dkr.ecr.eu-west-3.amazonaws.com/eks/kube-proxy:v1.21.2-eksbuild.2"
21m         Normal    Pulled                         pod/kube-proxy-zft5j                       Successfully pulled image "602401143452.dkr.ecr.eu-west-3.amazonaws.com/eks/kube-proxy:v1.21.2-eksbuild.2" in 5.973172005s
21m         Normal    Created                        pod/kube-proxy-zft5j                       Created container kube-proxy
21m         Normal    Started                        pod/kube-proxy-zft5j                       Started container kube-proxy
14m         Normal    ScaleDown                      pod/kube-proxy-zft5j                       deleting pod for node scale down
14m         Normal    Killing                        pod/kube-proxy-zft5j                       Stopping container kube-proxy
56m         Normal    SuccessfulCreate               daemonset/kube-proxy                       Created pod: kube-proxy-wj8dg
54m         Normal    SuccessfulCreate               daemonset/kube-proxy                       Created pod: kube-proxy-vwk72
48m         Normal    SuccessfulCreate               daemonset/kube-proxy                       Created pod: kube-proxy-6nqq8
40m         Normal    SuccessfulCreate               daemonset/kube-proxy                       Created pod: kube-proxy-fnscv
35m         Normal    SuccessfulCreate               daemonset/kube-proxy                       (combined from similar events): Created pod: kube-proxy-qsj4w
21m         Normal    SuccessfulCreate               daemonset/kube-proxy                       Created pod: kube-proxy-rvm55
21m         Normal    SuccessfulCreate               daemonset/kube-proxy                       Created pod: kube-proxy-zft5j
21m         Normal    SuccessfulCreate               daemonset/kube-proxy                       Created pod: kube-proxy-q9nwx
21m         Normal    SuccessfulCreate               daemonset/kube-proxy                       Created pod: kube-proxy-hslqr
21m         Normal    SuccessfulCreate               daemonset/kube-proxy                       Created pod: kube-proxy-6nqhz
14m         Normal    SuccessfulCreate               daemonset/kube-proxy                       Created pod: kube-proxy-v6vpk
12m         Normal    SuccessfulCreate               daemonset/kube-proxy                       Created pod: kube-proxy-2jlbc
11m         Normal    Scheduled                      pod/kubed-6b446694ff-m2kkx                 Successfully assigned kube-system/kubed-6b446694ff-m2kkx to ip-10-1-26-106.eu-west-3.compute.internal
11m         Normal    Pulling                        pod/kubed-6b446694ff-m2kkx                 Pulling image "appscode/kubed:v0.12.0"
11m         Normal    Pulled                         pod/kubed-6b446694ff-m2kkx                 Successfully pulled image "appscode/kubed:v0.12.0" in 4.53410349s
11m         Normal    Created                        pod/kubed-6b446694ff-m2kkx                 Created container kubed
11m         Normal    Started                        pod/kubed-6b446694ff-m2kkx                 Started container kubed
14m         Normal    Scheduled                      pod/kubed-6b446694ff-tdgr7                 Successfully assigned kube-system/kubed-6b446694ff-tdgr7 to ip-10-1-37-225.eu-west-3.compute.internal
14m         Normal    Pulling                        pod/kubed-6b446694ff-tdgr7                 Pulling image "appscode/kubed:v0.12.0"
14m         Normal    Pulled                         pod/kubed-6b446694ff-tdgr7                 Successfully pulled image "appscode/kubed:v0.12.0" in 3.589393969s
14m         Normal    Created                        pod/kubed-6b446694ff-tdgr7                 Created container kubed
14m         Normal    Started                        pod/kubed-6b446694ff-tdgr7                 Started container kubed
12m         Warning   NodeNotReady                   pod/kubed-6b446694ff-tdgr7                 Node is not ready
11m         Normal    TaintManagerEviction           pod/kubed-6b446694ff-tdgr7                 Cancelling deletion of Pod kube-system/kubed-6b446694ff-tdgr7
29m         Normal    Killing                        pod/kubed-6b446694ff-vtl87                 Stopping container kubed
28m         Warning   FailedScheduling               pod/kubed-6b446694ff-wsknb                 0/5 nodes are available: 5 node(s) were unschedulable.
28m         Warning   FailedScheduling               pod/kubed-6b446694ff-wsknb                 0/3 nodes are available: 3 node(s) were unschedulable.
21m         Warning   FailedScheduling               pod/kubed-6b446694ff-wsknb                 no nodes available to schedule pods
21m         Warning   FailedScheduling               pod/kubed-6b446694ff-wsknb                 0/3 nodes are available: 3 node(s) had taint {node.kubernetes.io/not-ready: }, that the pod didn't tolerate.
21m         Warning   FailedScheduling               pod/kubed-6b446694ff-wsknb                 0/5 nodes are available: 5 node(s) had taint {node.kubernetes.io/not-ready: }, that the pod didn't tolerate.
20m         Normal    Scheduled                      pod/kubed-6b446694ff-wsknb                 Successfully assigned kube-system/kubed-6b446694ff-wsknb to ip-10-1-12-138.eu-west-3.compute.internal
20m         Normal    Pulling                        pod/kubed-6b446694ff-wsknb                 Pulling image "appscode/kubed:v0.12.0"
20m         Normal    Pulled                         pod/kubed-6b446694ff-wsknb                 Successfully pulled image "appscode/kubed:v0.12.0" in 3.677007737s
20m         Normal    Created                        pod/kubed-6b446694ff-wsknb                 Created container kubed
20m         Normal    Started                        pod/kubed-6b446694ff-wsknb                 Started container kubed
14m         Normal    ScaleDown                      pod/kubed-6b446694ff-wsknb                 deleting pod for node scale down
14m         Normal    Killing                        pod/kubed-6b446694ff-wsknb                 Stopping container kubed
29m         Normal    SuccessfulCreate               replicaset/kubed-6b446694ff                Created pod: kubed-6b446694ff-wsknb
14m         Normal    SuccessfulCreate               replicaset/kubed-6b446694ff                Created pod: kubed-6b446694ff-tdgr7
11m         Normal    SuccessfulCreate               replicaset/kubed-6b446694ff                Created pod: kubed-6b446694ff-m2kkx
56m         Normal    Scheduled                      pod/metrics-server-645499f5cf-ftf45        Successfully assigned kube-system/metrics-server-645499f5cf-ftf45 to ip-10-1-29-31.eu-west-3.compute.internal
56m         Normal    Pulling                        pod/metrics-server-645499f5cf-ftf45        Pulling image "hub.simloudcorp.customers.simloud.com/metrics-server/metrics-server:v0.6.0"
56m         Normal    Pulled                         pod/metrics-server-645499f5cf-ftf45        Successfully pulled image "hub.simloudcorp.customers.simloud.com/metrics-server/metrics-server:v0.6.0" in 3.278886694s
56m         Normal    Created                        pod/metrics-server-645499f5cf-ftf45        Created container metrics-server
56m         Normal    Started                        pod/metrics-server-645499f5cf-ftf45        Started container metrics-server
35m         Warning   Unhealthy                      pod/metrics-server-645499f5cf-ftf45        Liveness probe failed: Get "https://10.1.7.92:8443/healthz": net/http: request canceled while waiting for connection (Client.Timeout exceeded while awaiting headers)
35m         Warning   Unhealthy                      pod/metrics-server-645499f5cf-ftf45        Readiness probe failed: Get "https://10.1.7.92:8443/healthz": net/http: request canceled (Client.Timeout exceeded while awaiting headers)
29m         Normal    Killing                        pod/metrics-server-645499f5cf-ftf45        Stopping container metrics-server
56m         Normal    ScaleDown                      pod/metrics-server-645499f5cf-h969p        deleting pod for node scale down
56m         Normal    Killing                        pod/metrics-server-645499f5cf-h969p        Stopping container metrics-server
20m         Normal    Scheduled                      pod/metrics-server-645499f5cf-rbcfl        Successfully assigned kube-system/metrics-server-645499f5cf-rbcfl to ip-10-1-62-180.eu-west-3.compute.internal
20m         Normal    Pulling                        pod/metrics-server-645499f5cf-rbcfl        Pulling image "hub.simloudcorp.customers.simloud.com/metrics-server/metrics-server:v0.6.0"
20m         Normal    Pulled                         pod/metrics-server-645499f5cf-rbcfl        Successfully pulled image "hub.simloudcorp.customers.simloud.com/metrics-server/metrics-server:v0.6.0" in 8.86035238s
20m         Normal    Created                        pod/metrics-server-645499f5cf-rbcfl        Created container metrics-server
20m         Normal    Started                        pod/metrics-server-645499f5cf-rbcfl        Started container metrics-server
11m         Warning   Unhealthy                      pod/metrics-server-645499f5cf-rbcfl        Liveness probe failed: Get "https://10.1.36.162:8443/healthz": net/http: request canceled (Client.Timeout exceeded while awaiting headers)
11m         Warning   Unhealthy                      pod/metrics-server-645499f5cf-rbcfl        Readiness probe failed: Get "https://10.1.36.162:8443/healthz": net/http: request canceled (Client.Timeout exceeded while awaiting headers)
56m         Normal    SuccessfulCreate               replicaset/metrics-server-645499f5cf       Created pod: metrics-server-645499f5cf-ftf45
29m         Normal    SuccessfulDelete               replicaset/metrics-server-645499f5cf       Deleted pod: metrics-server-645499f5cf-ftf45
20m         Normal    SuccessfulCreate               replicaset/metrics-server-645499f5cf       Created pod: metrics-server-645499f5cf-rbcfl
20m         Normal    ScalingReplicaSet              deployment/metrics-server                  Scaled up replica set metrics-server-645499f5cf to 1
29m         Normal    ScalingReplicaSet              deployment/metrics-server                  Scaled down replica set metrics-server-645499f5cf to 0
56m         Warning   Unhealthy                      pod/vault-0                                Readiness probe failed: Error checking leader status: Error making API request.

URL: GET http://127.0.0.1:8200/v1/sys/leader
Code: 500. Errors:

* Unexpected response code: 500
56m         Warning   Unhealthy                      pod/vault-0                                    Readiness probe failed:
29m         Normal    Killing                        pod/vault-0                                    Stopping container vault
29m         Warning   Unhealthy                      pod/vault-0                                    Readiness probe failed: Error checking seal status: Get "http://127.0.0.1:8200/v1/sys/seal-status": dial tcp 127.0.0.1:8200: connect: connection refused
20m         Normal    Scheduled                      pod/vault-0                                    Successfully assigned kube-system/vault-0 to ip-10-1-51-246.eu-west-3.compute.internal
20m         Normal    Pulling                        pod/vault-0                                    Pulling image "hub.simloudcorp.customers.simloud.com/simloud/vault/vault:1.9.2-1"
19m         Normal    Pulled                         pod/vault-0                                    Successfully pulled image "hub.simloudcorp.customers.simloud.com/simloud/vault/vault:1.9.2-1" in 32.901177814s
19m         Normal    Created                        pod/vault-0                                    Created container vault
19m         Normal    Started                        pod/vault-0                                    Started container vault
14m         Warning   Unhealthy                      pod/vault-0                                    Readiness probe failed:
29m         Normal    Killing                        pod/vault-1                                    Stopping container vault
29m         Warning   Unhealthy                      pod/vault-1                                    Readiness probe failed:
29m         Warning   Unhealthy                      pod/vault-1                                    Readiness probe failed: Error checking seal status: Get "http://127.0.0.1:8200/v1/sys/seal-status": dial tcp 127.0.0.1:8200: connect: connection refused
20m         Normal    Scheduled                      pod/vault-1                                    Successfully assigned kube-system/vault-1 to ip-10-1-0-97.eu-west-3.compute.internal
20m         Normal    Pulling                        pod/vault-1                                    Pulling image "hub.simloudcorp.customers.simloud.com/simloud/vault/vault:1.9.2-1"
19m         Normal    Pulled                         pod/vault-1                                    Successfully pulled image "hub.simloudcorp.customers.simloud.com/simloud/vault/vault:1.9.2-1" in 33.743157986s
19m         Normal    Created                        pod/vault-1                                    Created container vault
19m         Normal    Started                        pod/vault-1                                    Started container vault
12m         Warning   Unhealthy                      pod/vault-1                                    Readiness probe failed:
29m         Normal    Killing                        pod/vault-agent-injector-57d87ff44f-585c5      Stopping container leader-elector
29m         Normal    Killing                        pod/vault-agent-injector-57d87ff44f-585c5      Stopping container sidecar-injector
29m         Warning   Unhealthy                      pod/vault-agent-injector-57d87ff44f-585c5      Readiness probe failed: Get "https://10.1.61.103:8080/health/ready": dial tcp 10.1.61.103:8080: connect: connection refused
29m         Warning   Unhealthy                      pod/vault-agent-injector-57d87ff44f-585c5      Liveness probe failed: Get "https://10.1.61.103:8080/health/ready": dial tcp 10.1.61.103:8080: connect: connection refused
20m         Normal    Scheduled                      pod/vault-agent-injector-57d87ff44f-dhnq2      Successfully assigned kube-system/vault-agent-injector-57d87ff44f-dhnq2 to ip-10-1-62-180.eu-west-3.compute.internal
20m         Normal    Pulling                        pod/vault-agent-injector-57d87ff44f-dhnq2      Pulling image "hub.simloudcorp.customers.simloud.com/hashicorp/vault-k8s:0.14.2"
20m         Normal    Pulled                         pod/vault-agent-injector-57d87ff44f-dhnq2      Successfully pulled image "hub.simloudcorp.customers.simloud.com/hashicorp/vault-k8s:0.14.2" in 6.982199814s
20m         Normal    Created                        pod/vault-agent-injector-57d87ff44f-dhnq2      Created container sidecar-injector
20m         Normal    Started                        pod/vault-agent-injector-57d87ff44f-dhnq2      Started container sidecar-injector
20m         Normal    Pulling                        pod/vault-agent-injector-57d87ff44f-dhnq2      Pulling image "hub.simloudcorp.customers.simloud.com/google_containers/leader-elector:0.4"
19m         Normal    Pulled                         pod/vault-agent-injector-57d87ff44f-dhnq2      Successfully pulled image "hub.simloudcorp.customers.simloud.com/google_containers/leader-elector:0.4" in 14.705579s
19m         Normal    Created                        pod/vault-agent-injector-57d87ff44f-dhnq2      Created container leader-elector
19m         Normal    Started                        pod/vault-agent-injector-57d87ff44f-dhnq2      Started container leader-elector
20m         Normal    Scheduled                      pod/vault-agent-injector-57d87ff44f-dtglt      Successfully assigned kube-system/vault-agent-injector-57d87ff44f-dtglt to ip-10-1-51-246.eu-west-3.compute.internal
20m         Normal    Pulling                        pod/vault-agent-injector-57d87ff44f-dtglt      Pulling image "hub.simloudcorp.customers.simloud.com/hashicorp/vault-k8s:0.14.2"
20m         Normal    Pulled                         pod/vault-agent-injector-57d87ff44f-dtglt      Successfully pulled image "hub.simloudcorp.customers.simloud.com/hashicorp/vault-k8s:0.14.2" in 6.848933299s
20m         Normal    Created                        pod/vault-agent-injector-57d87ff44f-dtglt      Created container sidecar-injector
20m         Normal    Started                        pod/vault-agent-injector-57d87ff44f-dtglt      Started container sidecar-injector
20m         Normal    Pulling                        pod/vault-agent-injector-57d87ff44f-dtglt      Pulling image "hub.simloudcorp.customers.simloud.com/google_containers/leader-elector:0.4"
19m         Normal    Pulled                         pod/vault-agent-injector-57d87ff44f-dtglt      Successfully pulled image "hub.simloudcorp.customers.simloud.com/google_containers/leader-elector:0.4" in 17.357872741s
19m         Normal    Created                        pod/vault-agent-injector-57d87ff44f-dtglt      Created container leader-elector
19m         Normal    Started                        pod/vault-agent-injector-57d87ff44f-dtglt      Started container leader-elector
36m         Normal    Scheduled                      pod/vault-agent-injector-57d87ff44f-k7b2r      Successfully assigned kube-system/vault-agent-injector-57d87ff44f-k7b2r to ip-10-1-38-3.eu-west-3.compute.internal
36m         Normal    Pulling                        pod/vault-agent-injector-57d87ff44f-k7b2r      Pulling image "hub.simloudcorp.customers.simloud.com/hashicorp/vault-k8s:0.14.2"
36m         Normal    Pulled                         pod/vault-agent-injector-57d87ff44f-k7b2r      Successfully pulled image "hub.simloudcorp.customers.simloud.com/hashicorp/vault-k8s:0.14.2" in 1.986302849s
36m         Normal    Created                        pod/vault-agent-injector-57d87ff44f-k7b2r      Created container sidecar-injector
36m         Normal    Started                        pod/vault-agent-injector-57d87ff44f-k7b2r      Started container sidecar-injector
36m         Normal    Pulling                        pod/vault-agent-injector-57d87ff44f-k7b2r      Pulling image "hub.simloudcorp.customers.simloud.com/google_containers/leader-elector:0.4"
36m         Normal    Pulled                         pod/vault-agent-injector-57d87ff44f-k7b2r      Successfully pulled image "hub.simloudcorp.customers.simloud.com/google_containers/leader-elector:0.4" in 5.207772598s
36m         Normal    Created                        pod/vault-agent-injector-57d87ff44f-k7b2r      Created container leader-elector
36m         Normal    Started                        pod/vault-agent-injector-57d87ff44f-k7b2r      Started container leader-elector
29m         Normal    Killing                        pod/vault-agent-injector-57d87ff44f-k7b2r      Stopping container sidecar-injector
29m         Normal    Killing                        pod/vault-agent-injector-57d87ff44f-k7b2r      Stopping container leader-elector
29m         Warning   Unhealthy                      pod/vault-agent-injector-57d87ff44f-k7b2r      Liveness probe failed: Get "https://10.1.46.72:8080/health/ready": dial tcp 10.1.46.72:8080: connect: connection refused
29m         Warning   Unhealthy                      pod/vault-agent-injector-57d87ff44f-k7b2r      Readiness probe failed: Get "https://10.1.46.72:8080/health/ready": dial tcp 10.1.46.72:8080: connect: connection refused
56m         Normal    Scheduled                      pod/vault-agent-injector-57d87ff44f-lvtdq      Successfully assigned kube-system/vault-agent-injector-57d87ff44f-lvtdq to ip-10-1-29-31.eu-west-3.compute.internal
56m         Normal    Pulling                        pod/vault-agent-injector-57d87ff44f-lvtdq      Pulling image "hub.simloudcorp.customers.simloud.com/hashicorp/vault-k8s:0.14.2"
56m         Normal    Pulled                         pod/vault-agent-injector-57d87ff44f-lvtdq      Successfully pulled image "hub.simloudcorp.customers.simloud.com/hashicorp/vault-k8s:0.14.2" in 2.918378544s
56m         Normal    Created                        pod/vault-agent-injector-57d87ff44f-lvtdq      Created container sidecar-injector
56m         Normal    Started                        pod/vault-agent-injector-57d87ff44f-lvtdq      Started container sidecar-injector
56m         Normal    Pulling                        pod/vault-agent-injector-57d87ff44f-lvtdq      Pulling image "hub.simloudcorp.customers.simloud.com/google_containers/leader-elector:0.4"
56m         Normal    Pulled                         pod/vault-agent-injector-57d87ff44f-lvtdq      Successfully pulled image "hub.simloudcorp.customers.simloud.com/google_containers/leader-elector:0.4" in 6.540821558s
56m         Normal    Created                        pod/vault-agent-injector-57d87ff44f-lvtdq      Created container leader-elector
56m         Normal    Started                        pod/vault-agent-injector-57d87ff44f-lvtdq      Started container leader-elector
29m         Normal    Killing                        pod/vault-agent-injector-57d87ff44f-lvtdq      Stopping container sidecar-injector
29m         Normal    Killing                        pod/vault-agent-injector-57d87ff44f-lvtdq      Stopping container leader-elector
29m         Warning   Unhealthy                      pod/vault-agent-injector-57d87ff44f-lvtdq      Liveness probe failed: Get "https://10.1.27.214:8080/health/ready": dial tcp 10.1.27.214:8080: connect: connection refused
29m         Warning   Unhealthy                      pod/vault-agent-injector-57d87ff44f-lvtdq      Readiness probe failed: Get "https://10.1.27.214:8080/health/ready": dial tcp 10.1.27.214:8080: connect: connection refused
56m         Normal    ScaleDown                      pod/vault-agent-injector-57d87ff44f-qq88s      deleting pod for node scale down
56m         Normal    Killing                        pod/vault-agent-injector-57d87ff44f-qq88s      Stopping container sidecar-injector
56m         Normal    Killing                        pod/vault-agent-injector-57d87ff44f-qq88s      Stopping container leader-elector
56m         Warning   Unhealthy                      pod/vault-agent-injector-57d87ff44f-qq88s      Liveness probe failed: Get "https://10.1.60.204:8080/health/ready": dial tcp 10.1.60.204:8080: connect: connection refused
56m         Warning   Unhealthy                      pod/vault-agent-injector-57d87ff44f-qq88s      Readiness probe failed: Get "https://10.1.60.204:8080/health/ready": dial tcp 10.1.60.204:8080: connect: connection refused
20m         Normal    Scheduled                      pod/vault-agent-injector-57d87ff44f-t9mw8      Successfully assigned kube-system/vault-agent-injector-57d87ff44f-t9mw8 to ip-10-1-12-138.eu-west-3.compute.internal
20m         Normal    Pulling                        pod/vault-agent-injector-57d87ff44f-t9mw8      Pulling image "hub.simloudcorp.customers.simloud.com/hashicorp/vault-k8s:0.14.2"
20m         Normal    Pulled                         pod/vault-agent-injector-57d87ff44f-t9mw8      Successfully pulled image "hub.simloudcorp.customers.simloud.com/hashicorp/vault-k8s:0.14.2" in 4.254266069s
20m         Normal    Created                        pod/vault-agent-injector-57d87ff44f-t9mw8      Created container sidecar-injector
20m         Normal    Started                        pod/vault-agent-injector-57d87ff44f-t9mw8      Started container sidecar-injector
20m         Normal    Pulling                        pod/vault-agent-injector-57d87ff44f-t9mw8      Pulling image "hub.simloudcorp.customers.simloud.com/google_containers/leader-elector:0.4"
19m         Normal    Pulled                         pod/vault-agent-injector-57d87ff44f-t9mw8      Successfully pulled image "hub.simloudcorp.customers.simloud.com/google_containers/leader-elector:0.4" in 10.997279443s
19m         Normal    Created                        pod/vault-agent-injector-57d87ff44f-t9mw8      Created container leader-elector
19m         Normal    Started                        pod/vault-agent-injector-57d87ff44f-t9mw8      Started container leader-elector
14m         Normal    ScaleDown                      pod/vault-agent-injector-57d87ff44f-t9mw8      deleting pod for node scale down
14m         Normal    Killing                        pod/vault-agent-injector-57d87ff44f-t9mw8      Stopping container sidecar-injector
14m         Normal    Killing                        pod/vault-agent-injector-57d87ff44f-t9mw8      Stopping container leader-elector
14m         Warning   Unhealthy                      pod/vault-agent-injector-57d87ff44f-t9mw8      Liveness probe failed: Get "https://10.1.15.233:8080/health/ready": dial tcp 10.1.15.233:8080: connect: connection refused
13m         Warning   Unhealthy                      pod/vault-agent-injector-57d87ff44f-t9mw8      Readiness probe failed: Get "https://10.1.15.233:8080/health/ready": dial tcp 10.1.15.233:8080: connect: connection refused
40m         Normal    Scheduled                      pod/vault-agent-injector-57d87ff44f-tfcrc      Successfully assigned kube-system/vault-agent-injector-57d87ff44f-tfcrc to ip-10-1-1-25.eu-west-3.compute.internal
40m         Normal    Pulling                        pod/vault-agent-injector-57d87ff44f-tfcrc      Pulling image "hub.simloudcorp.customers.simloud.com/hashicorp/vault-k8s:0.14.2"
39m         Normal    Pulled                         pod/vault-agent-injector-57d87ff44f-tfcrc      Successfully pulled image "hub.simloudcorp.customers.simloud.com/hashicorp/vault-k8s:0.14.2" in 2.414833688s
39m         Normal    Created                        pod/vault-agent-injector-57d87ff44f-tfcrc      Created container sidecar-injector
39m         Normal    Started                        pod/vault-agent-injector-57d87ff44f-tfcrc      Started container sidecar-injector
39m         Normal    Pulling                        pod/vault-agent-injector-57d87ff44f-tfcrc      Pulling image "hub.simloudcorp.customers.simloud.com/google_containers/leader-elector:0.4"
39m         Normal    Pulled                         pod/vault-agent-injector-57d87ff44f-tfcrc      Successfully pulled image "hub.simloudcorp.customers.simloud.com/google_containers/leader-elector:0.4" in 6.061007366s
39m         Normal    Created                        pod/vault-agent-injector-57d87ff44f-tfcrc      Created container leader-elector
39m         Normal    Started                        pod/vault-agent-injector-57d87ff44f-tfcrc      Started container leader-elector
38m         Warning   NodeNotReady                   pod/vault-agent-injector-57d87ff44f-tfcrc      Node is not ready
36m         Normal    TaintManagerEviction           pod/vault-agent-injector-57d87ff44f-tfcrc      Cancelling deletion of Pod kube-system/vault-agent-injector-57d87ff44f-tfcrc
53m         Normal    Scheduled                      pod/vault-agent-injector-57d87ff44f-vtsc7      Successfully assigned kube-system/vault-agent-injector-57d87ff44f-vtsc7 to ip-10-1-52-192.eu-west-3.compute.internal
53m         Normal    Pulling                        pod/vault-agent-injector-57d87ff44f-vtsc7      Pulling image "hub.simloudcorp.customers.simloud.com/hashicorp/vault-k8s:0.14.2"
53m         Normal    Pulled                         pod/vault-agent-injector-57d87ff44f-vtsc7      Successfully pulled image "hub.simloudcorp.customers.simloud.com/hashicorp/vault-k8s:0.14.2" in 3.260125332s
53m         Normal    Created                        pod/vault-agent-injector-57d87ff44f-vtsc7      Created container sidecar-injector
53m         Normal    Started                        pod/vault-agent-injector-57d87ff44f-vtsc7      Started container sidecar-injector
53m         Normal    Pulling                        pod/vault-agent-injector-57d87ff44f-vtsc7      Pulling image "hub.simloudcorp.customers.simloud.com/google_containers/leader-elector:0.4"
53m         Normal    Pulled                         pod/vault-agent-injector-57d87ff44f-vtsc7      Successfully pulled image "hub.simloudcorp.customers.simloud.com/google_containers/leader-elector:0.4" in 8.517527176s
53m         Normal    Created                        pod/vault-agent-injector-57d87ff44f-vtsc7      Created container leader-elector
53m         Normal    Started                        pod/vault-agent-injector-57d87ff44f-vtsc7      Started container leader-elector
40m         Normal    ScaleDown                      pod/vault-agent-injector-57d87ff44f-vtsc7      deleting pod for node scale down
40m         Normal    Killing                        pod/vault-agent-injector-57d87ff44f-vtsc7      Stopping container sidecar-injector
40m         Normal    Killing                        pod/vault-agent-injector-57d87ff44f-vtsc7      Stopping container leader-elector
39m         Warning   Unhealthy                      pod/vault-agent-injector-57d87ff44f-vtsc7      Readiness probe failed: Get "https://10.1.58.156:8080/health/ready": dial tcp 10.1.58.156:8080: connect: connection refused
40m         Warning   Unhealthy                      pod/vault-agent-injector-57d87ff44f-vtsc7      Liveness probe failed: Get "https://10.1.58.156:8080/health/ready": dial tcp 10.1.58.156:8080: connect: connection refused
14m         Normal    Scheduled                      pod/vault-agent-injector-57d87ff44f-wtxfj      Successfully assigned kube-system/vault-agent-injector-57d87ff44f-wtxfj to ip-10-1-0-97.eu-west-3.compute.internal
14m         Normal    Pulling                        pod/vault-agent-injector-57d87ff44f-wtxfj      Pulling image "hub.simloudcorp.customers.simloud.com/hashicorp/vault-k8s:0.14.2"
14m         Normal    Pulled                         pod/vault-agent-injector-57d87ff44f-wtxfj      Successfully pulled image "hub.simloudcorp.customers.simloud.com/hashicorp/vault-k8s:0.14.2" in 2.602926085s
14m         Normal    Created                        pod/vault-agent-injector-57d87ff44f-wtxfj      Created container sidecar-injector
14m         Normal    Started                        pod/vault-agent-injector-57d87ff44f-wtxfj      Started container sidecar-injector
14m         Normal    Pulling                        pod/vault-agent-injector-57d87ff44f-wtxfj      Pulling image "hub.simloudcorp.customers.simloud.com/google_containers/leader-elector:0.4"
14m         Normal    Pulled                         pod/vault-agent-injector-57d87ff44f-wtxfj      Successfully pulled image "hub.simloudcorp.customers.simloud.com/google_containers/leader-elector:0.4" in 6.296469019s
14m         Normal    Created                        pod/vault-agent-injector-57d87ff44f-wtxfj      Created container leader-elector
14m         Normal    Started                        pod/vault-agent-injector-57d87ff44f-wtxfj      Started container leader-elector
55m         Warning   NodeNotReady                   pod/vault-agent-injector-57d87ff44f-z22fs      Node is not ready
53m         Normal    TaintManagerEviction           pod/vault-agent-injector-57d87ff44f-z22fs      Cancelling deletion of Pod kube-system/vault-agent-injector-57d87ff44f-z22fs
56m         Normal    SuccessfulCreate               replicaset/vault-agent-injector-57d87ff44f     Created pod: vault-agent-injector-57d87ff44f-lvtdq
53m         Normal    SuccessfulCreate               replicaset/vault-agent-injector-57d87ff44f     Created pod: vault-agent-injector-57d87ff44f-vtsc7
40m         Normal    SuccessfulCreate               replicaset/vault-agent-injector-57d87ff44f     Created pod: vault-agent-injector-57d87ff44f-tfcrc
36m         Normal    SuccessfulCreate               replicaset/vault-agent-injector-57d87ff44f     Created pod: vault-agent-injector-57d87ff44f-k7b2r
29m         Normal    SuccessfulDelete               replicaset/vault-agent-injector-57d87ff44f     Deleted pod: vault-agent-injector-57d87ff44f-k7b2r
29m         Normal    SuccessfulDelete               replicaset/vault-agent-injector-57d87ff44f     Deleted pod: vault-agent-injector-57d87ff44f-585c5
29m         Normal    SuccessfulDelete               replicaset/vault-agent-injector-57d87ff44f     Deleted pod: vault-agent-injector-57d87ff44f-lvtdq
20m         Normal    SuccessfulCreate               replicaset/vault-agent-injector-57d87ff44f     Created pod: vault-agent-injector-57d87ff44f-t9mw8
20m         Normal    SuccessfulCreate               replicaset/vault-agent-injector-57d87ff44f     Created pod: vault-agent-injector-57d87ff44f-dhnq2
20m         Normal    SuccessfulCreate               replicaset/vault-agent-injector-57d87ff44f     Created pod: vault-agent-injector-57d87ff44f-dtglt
14m         Normal    SuccessfulCreate               replicaset/vault-agent-injector-57d87ff44f     Created pod: vault-agent-injector-57d87ff44f-wtxfj
29m         Warning   FailedToUpdateEndpoint         endpoints/vault-agent-injector-svc             Failed to update endpoint kube-system/vault-agent-injector-svc: Operation cannot be fulfilled on endpoints "vault-agent-injector-svc": the object has been modified; please apply your changes to the latest version and try again
20m         Normal    ScalingReplicaSet              deployment/vault-agent-injector                Scaled up replica set vault-agent-injector-57d87ff44f to 3
41s         Warning   FailedGetResourceMetric        horizontalpodautoscaler/vault-agent-injector   failed to get cpu utilization: missing request for cpu
29m         Normal    ScalingReplicaSet              deployment/vault-agent-injector                Scaled down replica set vault-agent-injector-57d87ff44f to 0
20m         Warning   FailedGetResourceMetric        horizontalpodautoscaler/vault-agent-injector   failed to get cpu utilization: unable to get metrics for resource cpu: unable to fetch metrics from resource metrics API: the server is currently unable to handle the request (get pods.metrics.k8s.io)
20m         Warning   FailedComputeMetricsReplicas   horizontalpodautoscaler/vault-agent-injector   invalid metrics (1 invalid out of 1), first error is: failed to get cpu utilization: unable to get metrics for resource cpu: unable to fetch metrics from resource metrics API: the server is currently unable to handle the request (get pods.metrics.k8s.io)
29m         Normal    NoPods                         poddisruptionbudget/vault                      No matching pods found
20m         Normal    SuccessfulCreate               statefulset/vault                              create Pod vault-0 in StatefulSet vault successful
20m         Normal    SuccessfulCreate               statefulset/vault                              create Pod vault-1 in StatefulSet vault successful
29m         Normal    SuccessfulDelete               statefulset/vault                              delete Pod vault-1 in StatefulSet vault successful
29m         Normal    SuccessfulDelete               statefulset/vault                              delete Pod vault-0 in StatefulSet vault successful
54m         Normal    CREATE                         ingress/vault                                  Ingress kube-system/vault
47m         Normal    CREATE                         ingress/vault                                  Ingress kube-system/vault
37m         Normal    CREATE                         ingress/vault                                  Ingress kube-system/vault
34m         Normal    CREATE                         ingress/vault                                  Ingress kube-system/vault
20m         Normal    CREATE                         ingress/vault                                  Ingress kube-system/vault
20m         Normal    CREATE                         ingress/vault                                  Ingress kube-system/vault
19m         Normal    CREATE                         ingress/vault                                  Ingress kube-system/vault
19m         Normal    CREATE                         ingress/vault                                  Ingress kube-system/vault
19m         Normal    CREATE                         ingress/vault                                  Ingress kube-system/vault
19m         Normal    UPDATE                         ingress/vault                                  Ingress kube-system/vault
19m         Normal    UPDATE                         ingress/vault                                  Ingress kube-system/vault
19m         Normal    UPDATE                         ingress/vault                                  Ingress kube-system/vault
19m         Normal    UPDATE                         ingress/vault                                  Ingress kube-system/vault
19m         Normal    UPDATE                         ingress/vault                                  Ingress kube-system/vault
11m         Normal    CREATE                         ingress/vault                                  Ingress kube-system/vault
